2022-09-06 11:19:23,420: Unable to parse expressions: 'type' object is not subscriptable (trace: Traceback (most recent call last):
  File "C:\WorkingCopies\Github\sparameterviewer\src\sparamviewer_main.py", line 717, in update_plot
    ExpressionParser.eval(self.generated_expressions, self.files, self.get_selected_files(), add_to_plot)
  File "C:\WorkingCopies\Github\sparameterviewer\src\lib\expressions\expressions.py", line 22, in eval
    def select_networks(network_list: list[SParamFile], pattern: str, single: bool) -> Networks:
TypeError: 'type' object is not subscriptable
) (sparamviewer_main.py:720:update_plot, ERROR)
2022-09-06 11:19:23,662: Unable to parse expressions: 'type' object is not subscriptable (trace: Traceback (most recent call last):
  File "C:\WorkingCopies\Github\sparameterviewer\src\sparamviewer_main.py", line 717, in update_plot
    ExpressionParser.eval(self.generated_expressions, self.files, self.get_selected_files(), add_to_plot)
  File "C:\WorkingCopies\Github\sparameterviewer\src\lib\expressions\expressions.py", line 22, in eval
    def select_networks(network_list: list[SParamFile], pattern: str, single: bool) -> Networks:
TypeError: 'type' object is not subscriptable
) (sparamviewer_main.py:720:update_plot, ERROR)
2022-09-06 11:19:27,313: Unable to parse expressions: 'type' object is not subscriptable (trace: Traceback (most recent call last):
  File "C:\WorkingCopies\Github\sparameterviewer\src\sparamviewer_main.py", line 717, in update_plot
    ExpressionParser.eval(self.generated_expressions, self.files, self.get_selected_files(), add_to_plot)
  File "C:\WorkingCopies\Github\sparameterviewer\src\lib\expressions\expressions.py", line 22, in eval
    def select_networks(network_list: list[SParamFile], pattern: str, single: bool) -> Networks:
TypeError: 'type' object is not subscriptable
) (sparamviewer_main.py:720:update_plot, ERROR)
2022-09-06 11:23:24,412: Unable to parse expressions: 'type' object is not subscriptable (trace: Traceback (most recent call last):
  File "C:\WorkingCopies\Github\sparameterviewer/src\sparamviewer_main.py", line 717, in update_plot
    ExpressionParser.eval(self.generated_expressions, self.files, self.get_selected_files(), add_to_plot)
  File "C:\WorkingCopies\Github\sparameterviewer/src\lib\expressions\expressions.py", line 22, in eval
    def select_networks(network_list: list[SParamFile], pattern: str, single: bool) -> Networks:
TypeError: 'type' object is not subscriptable
) (sparamviewer_main.py:720:update_plot, ERROR)
2022-09-06 11:56:11,967: Plotting failed: type object 'LogCountHandler' has no attribute 'count' (sparamviewer_main.py:760:update_plot, ERROR)
Traceback (most recent call last):
  File "C:\WorkingCopies\Github\sparameterviewer/src\sparamviewer_main.py", line 688, in update_plot
    log_entries_before = self.logCountHandler.count
AttributeError: type object 'LogCountHandler' has no attribute 'count'
2022-09-06 11:58:27,281: Plotting failed: type object 'LogCountHandler' has no attribute 'count' (sparamviewer_main.py:760:update_plot, ERROR)
Traceback (most recent call last):
  File "C:\WorkingCopies\Github\sparameterviewer/src\sparamviewer_main.py", line 688, in update_plot
    log_entries_before = self.logCountHandler.count
AttributeError: type object 'LogCountHandler' has no attribute 'count'
2022-09-06 11:58:27,290: Unable to init main dialog: handle() missing 1 required positional argument: 'record' (sparamviewer_main.py:168:__init__, ERROR)
Traceback (most recent call last):
  File "C:\WorkingCopies\Github\sparameterviewer/src\sparamviewer_main.py", line 688, in update_plot
    log_entries_before = self.logCountHandler.count
AttributeError: type object 'LogCountHandler' has no attribute 'count'

During handling of the above exception, another exception occurred:

Traceback (most recent call last):
  File "C:\WorkingCopies\Github\sparameterviewer/src\sparamviewer_main.py", line 163, in __init__
    self.update_plot()
  File "C:\WorkingCopies\Github\sparameterviewer/src\sparamviewer_main.py", line 760, in update_plot
    logging.exception(f'Plotting failed: {ex}')
  File "C:\Python37\lib\logging\__init__.py", line 1964, in exception
    error(msg, *args, exc_info=exc_info, **kwargs)
  File "C:\Python37\lib\logging\__init__.py", line 1956, in error
    root.error(msg, *args, **kwargs)
  File "C:\Python37\lib\logging\__init__.py", line 1407, in error
    self._log(ERROR, msg, args, **kwargs)
  File "C:\Python37\lib\logging\__init__.py", line 1514, in _log
    self.handle(record)
  File "C:\Python37\lib\logging\__init__.py", line 1524, in handle
    self.callHandlers(record)
  File "C:\Python37\lib\logging\__init__.py", line 1586, in callHandlers
    hdlr.handle(record)
TypeError: handle() missing 1 required positional argument: 'record'
2022-09-06 11:58:27,298: Error in main loop: {ex} (sparamviewer.py:45:<module>, ERROR)
Traceback (most recent call last):
  File "C:\WorkingCopies\Github\sparameterviewer/src\sparamviewer_main.py", line 688, in update_plot
    log_entries_before = self.logCountHandler.count
AttributeError: type object 'LogCountHandler' has no attribute 'count'

During handling of the above exception, another exception occurred:

Traceback (most recent call last):
  File "C:\WorkingCopies\Github\sparameterviewer/src\sparamviewer_main.py", line 163, in __init__
    self.update_plot()
  File "C:\WorkingCopies\Github\sparameterviewer/src\sparamviewer_main.py", line 760, in update_plot
    logging.exception(f'Plotting failed: {ex}')
  File "C:\Python37\lib\logging\__init__.py", line 1964, in exception
    error(msg, *args, exc_info=exc_info, **kwargs)
  File "C:\Python37\lib\logging\__init__.py", line 1956, in error
    root.error(msg, *args, **kwargs)
  File "C:\Python37\lib\logging\__init__.py", line 1407, in error
    self._log(ERROR, msg, args, **kwargs)
  File "C:\Python37\lib\logging\__init__.py", line 1514, in _log
    self.handle(record)
  File "C:\Python37\lib\logging\__init__.py", line 1524, in handle
    self.callHandlers(record)
  File "C:\Python37\lib\logging\__init__.py", line 1586, in callHandlers
    hdlr.handle(record)
TypeError: handle() missing 1 required positional argument: 'record'

During handling of the above exception, another exception occurred:

Traceback (most recent call last):
  File "C:\WorkingCopies\Github\sparameterviewer/src/sparamviewer.py", line 42, in <module>
    app = SparamviewerMainDialog(filenames)
  File "C:\WorkingCopies\Github\sparameterviewer/src\sparamviewer_main.py", line 168, in __init__
    logging.exception(f'Unable to init main dialog: {ex}')
  File "C:\Python37\lib\logging\__init__.py", line 1964, in exception
    error(msg, *args, exc_info=exc_info, **kwargs)
  File "C:\Python37\lib\logging\__init__.py", line 1956, in error
    root.error(msg, *args, **kwargs)
  File "C:\Python37\lib\logging\__init__.py", line 1407, in error
    self._log(ERROR, msg, args, **kwargs)
  File "C:\Python37\lib\logging\__init__.py", line 1514, in _log
    self.handle(record)
  File "C:\Python37\lib\logging\__init__.py", line 1524, in handle
    self.callHandlers(record)
  File "C:\Python37\lib\logging\__init__.py", line 1586, in callHandlers
    hdlr.handle(record)
TypeError: handle() missing 1 required positional argument: 'record'
2022-09-06 12:01:18,477: Plotting failed: type object 'LogCountHandler' has no attribute 'count' (sparamviewer_main.py:760:update_plot, ERROR)
Traceback (most recent call last):
  File "C:\WorkingCopies\Github\sparameterviewer/src\sparamviewer_main.py", line 688, in update_plot
    log_entries_before = self.logCountHandler.count
AttributeError: type object 'LogCountHandler' has no attribute 'count'
2022-09-06 12:01:21,020: Plotting failed: type object 'LogCountHandler' has no attribute 'count' (sparamviewer_main.py:760:update_plot, ERROR)
Traceback (most recent call last):
  File "C:\WorkingCopies\Github\sparameterviewer/src\sparamviewer_main.py", line 688, in update_plot
    log_entries_before = self.logCountHandler.count
AttributeError: type object 'LogCountHandler' has no attribute 'count'
2022-09-06 12:01:26,621: Plotting failed: type object 'LogCountHandler' has no attribute 'count' (sparamviewer_main.py:760:update_plot, ERROR)
Traceback (most recent call last):
  File "C:\WorkingCopies\Github\sparameterviewer/src\sparamviewer_main.py", line 688, in update_plot
    log_entries_before = self.logCountHandler.count
AttributeError: type object 'LogCountHandler' has no attribute 'count'
2022-09-06 12:01:43,404: Plotting failed: type object 'LogCountHandler' has no attribute 'count' (sparamviewer_main.py:760:update_plot, ERROR)
Traceback (most recent call last):
  File "C:\WorkingCopies\Github\sparameterviewer/src\sparamviewer_main.py", line 688, in update_plot
    log_entries_before = self.logCountHandler.count
AttributeError: type object 'LogCountHandler' has no attribute 'count'
2022-09-06 12:01:43,415: Unable to init main dialog: handle() missing 1 required positional argument: 'record' (sparamviewer_main.py:168:__init__, ERROR)
Traceback (most recent call last):
  File "C:\WorkingCopies\Github\sparameterviewer/src\sparamviewer_main.py", line 688, in update_plot
    log_entries_before = self.logCountHandler.count
AttributeError: type object 'LogCountHandler' has no attribute 'count'

During handling of the above exception, another exception occurred:

Traceback (most recent call last):
  File "C:\WorkingCopies\Github\sparameterviewer/src\sparamviewer_main.py", line 163, in __init__
    self.update_plot()
  File "C:\WorkingCopies\Github\sparameterviewer/src\sparamviewer_main.py", line 760, in update_plot
    logging.exception(f'Plotting failed: {ex}')
  File "C:\Python37\lib\logging\__init__.py", line 1964, in exception
    error(msg, *args, exc_info=exc_info, **kwargs)
  File "C:\Python37\lib\logging\__init__.py", line 1956, in error
    root.error(msg, *args, **kwargs)
  File "C:\Python37\lib\logging\__init__.py", line 1407, in error
    self._log(ERROR, msg, args, **kwargs)
  File "C:\Python37\lib\logging\__init__.py", line 1514, in _log
    self.handle(record)
  File "C:\Python37\lib\logging\__init__.py", line 1524, in handle
    self.callHandlers(record)
  File "C:\Python37\lib\logging\__init__.py", line 1586, in callHandlers
    hdlr.handle(record)
TypeError: handle() missing 1 required positional argument: 'record'
2022-09-06 12:01:43,423: Error in main loop: {ex} (sparamviewer.py:45:<module>, ERROR)
Traceback (most recent call last):
  File "C:\WorkingCopies\Github\sparameterviewer/src\sparamviewer_main.py", line 688, in update_plot
    log_entries_before = self.logCountHandler.count
AttributeError: type object 'LogCountHandler' has no attribute 'count'

During handling of the above exception, another exception occurred:

Traceback (most recent call last):
  File "C:\WorkingCopies\Github\sparameterviewer/src\sparamviewer_main.py", line 163, in __init__
    self.update_plot()
  File "C:\WorkingCopies\Github\sparameterviewer/src\sparamviewer_main.py", line 760, in update_plot
    logging.exception(f'Plotting failed: {ex}')
  File "C:\Python37\lib\logging\__init__.py", line 1964, in exception
    error(msg, *args, exc_info=exc_info, **kwargs)
  File "C:\Python37\lib\logging\__init__.py", line 1956, in error
    root.error(msg, *args, **kwargs)
  File "C:\Python37\lib\logging\__init__.py", line 1407, in error
    self._log(ERROR, msg, args, **kwargs)
  File "C:\Python37\lib\logging\__init__.py", line 1514, in _log
    self.handle(record)
  File "C:\Python37\lib\logging\__init__.py", line 1524, in handle
    self.callHandlers(record)
  File "C:\Python37\lib\logging\__init__.py", line 1586, in callHandlers
    hdlr.handle(record)
TypeError: handle() missing 1 required positional argument: 'record'

During handling of the above exception, another exception occurred:

Traceback (most recent call last):
  File "C:\WorkingCopies\Github\sparameterviewer/src/sparamviewer.py", line 42, in <module>
    app = SparamviewerMainDialog(filenames)
  File "C:\WorkingCopies\Github\sparameterviewer/src\sparamviewer_main.py", line 168, in __init__
    logging.exception(f'Unable to init main dialog: {ex}')
  File "C:\Python37\lib\logging\__init__.py", line 1964, in exception
    error(msg, *args, exc_info=exc_info, **kwargs)
  File "C:\Python37\lib\logging\__init__.py", line 1956, in error
    root.error(msg, *args, **kwargs)
  File "C:\Python37\lib\logging\__init__.py", line 1407, in error
    self._log(ERROR, msg, args, **kwargs)
  File "C:\Python37\lib\logging\__init__.py", line 1514, in _log
    self.handle(record)
  File "C:\Python37\lib\logging\__init__.py", line 1524, in handle
    self.callHandlers(record)
  File "C:\Python37\lib\logging\__init__.py", line 1586, in callHandlers
    hdlr.handle(record)
TypeError: handle() missing 1 required positional argument: 'record'
2022-09-06 12:03:57,863: Plotting failed: type object 'LogCountHandler' has no attribute 'count' (sparamviewer_main.py:760:update_plot, ERROR)
Traceback (most recent call last):
  File "C:\WorkingCopies\Github\sparameterviewer/src\sparamviewer_main.py", line 688, in update_plot
    log_entries_before = self.logCountHandler.count
AttributeError: type object 'LogCountHandler' has no attribute 'count'
2022-09-06 12:06:03,211: Plotting failed: type object 'LogCountHandler' has no attribute 'count' (sparamviewer_main.py:760:update_plot, ERROR)
Traceback (most recent call last):
  File "C:\WorkingCopies\Github\sparameterviewer/src\sparamviewer_main.py", line 688, in update_plot
    log_entries_before = self.logCountHandler.count
AttributeError: type object 'LogCountHandler' has no attribute 'count'
2022-09-06 12:06:03,220: Unable to init main dialog: handle() missing 1 required positional argument: 'record' (sparamviewer_main.py:168:__init__, ERROR)
Traceback (most recent call last):
  File "C:\WorkingCopies\Github\sparameterviewer/src\sparamviewer_main.py", line 688, in update_plot
    log_entries_before = self.logCountHandler.count
AttributeError: type object 'LogCountHandler' has no attribute 'count'

During handling of the above exception, another exception occurred:

Traceback (most recent call last):
  File "C:\WorkingCopies\Github\sparameterviewer/src\sparamviewer_main.py", line 163, in __init__
    self.update_plot()
  File "C:\WorkingCopies\Github\sparameterviewer/src\sparamviewer_main.py", line 760, in update_plot
    logging.exception(f'Plotting failed: {ex}')
  File "C:\Python37\lib\logging\__init__.py", line 1964, in exception
    error(msg, *args, exc_info=exc_info, **kwargs)
  File "C:\Python37\lib\logging\__init__.py", line 1956, in error
    root.error(msg, *args, **kwargs)
  File "C:\Python37\lib\logging\__init__.py", line 1407, in error
    self._log(ERROR, msg, args, **kwargs)
  File "C:\Python37\lib\logging\__init__.py", line 1514, in _log
    self.handle(record)
  File "C:\Python37\lib\logging\__init__.py", line 1524, in handle
    self.callHandlers(record)
  File "C:\Python37\lib\logging\__init__.py", line 1586, in callHandlers
    hdlr.handle(record)
TypeError: handle() missing 1 required positional argument: 'record'
2022-09-06 12:06:03,227: Error in main loop: {ex} (sparamviewer.py:45:<module>, ERROR)
Traceback (most recent call last):
  File "C:\WorkingCopies\Github\sparameterviewer/src\sparamviewer_main.py", line 688, in update_plot
    log_entries_before = self.logCountHandler.count
AttributeError: type object 'LogCountHandler' has no attribute 'count'

During handling of the above exception, another exception occurred:

Traceback (most recent call last):
  File "C:\WorkingCopies\Github\sparameterviewer/src\sparamviewer_main.py", line 163, in __init__
    self.update_plot()
  File "C:\WorkingCopies\Github\sparameterviewer/src\sparamviewer_main.py", line 760, in update_plot
    logging.exception(f'Plotting failed: {ex}')
  File "C:\Python37\lib\logging\__init__.py", line 1964, in exception
    error(msg, *args, exc_info=exc_info, **kwargs)
  File "C:\Python37\lib\logging\__init__.py", line 1956, in error
    root.error(msg, *args, **kwargs)
  File "C:\Python37\lib\logging\__init__.py", line 1407, in error
    self._log(ERROR, msg, args, **kwargs)
  File "C:\Python37\lib\logging\__init__.py", line 1514, in _log
    self.handle(record)
  File "C:\Python37\lib\logging\__init__.py", line 1524, in handle
    self.callHandlers(record)
  File "C:\Python37\lib\logging\__init__.py", line 1586, in callHandlers
    hdlr.handle(record)
TypeError: handle() missing 1 required positional argument: 'record'

During handling of the above exception, another exception occurred:

Traceback (most recent call last):
  File "C:\WorkingCopies\Github\sparameterviewer/src/sparamviewer.py", line 42, in <module>
    app = SparamviewerMainDialog(filenames)
  File "C:\WorkingCopies\Github\sparameterviewer/src\sparamviewer_main.py", line 168, in __init__
    logging.exception(f'Unable to init main dialog: {ex}')
  File "C:\Python37\lib\logging\__init__.py", line 1964, in exception
    error(msg, *args, exc_info=exc_info, **kwargs)
  File "C:\Python37\lib\logging\__init__.py", line 1956, in error
    root.error(msg, *args, **kwargs)
  File "C:\Python37\lib\logging\__init__.py", line 1407, in error
    self._log(ERROR, msg, args, **kwargs)
  File "C:\Python37\lib\logging\__init__.py", line 1514, in _log
    self.handle(record)
  File "C:\Python37\lib\logging\__init__.py", line 1524, in handle
    self.callHandlers(record)
  File "C:\Python37\lib\logging\__init__.py", line 1586, in callHandlers
    hdlr.handle(record)
TypeError: handle() missing 1 required positional argument: 'record'
2022-09-06 12:06:25,710: Error in main loop: {ex} (sparamviewer.py:45:<module>, ERROR)
Traceback (most recent call last):
  File "C:\WorkingCopies\Github\sparameterviewer/src/sparamviewer.py", line 42, in <module>
    app = SparamviewerMainDialog(filenames)
  File "C:\WorkingCopies\Github\sparameterviewer/src\sparamviewer_main.py", line 35, in __init__
    self.logCountHandler = LogCountHandler()
  File "C:\WorkingCopies\Github\sparameterviewer/src\lib\log_counter_handler.py", line 8, in __init__
    super().__init__(self)
  File "C:\Python37\lib\logging\__init__.py", line 809, in __init__
    self.level = _checkLevel(level)
  File "C:\Python37\lib\logging\__init__.py", line 190, in _checkLevel
    elif str(level) == level:
  File "C:\Python37\lib\logging\__init__.py", line 979, in __repr__
    level = getLevelName(self.level)
AttributeError: 'LogCountHandler' object has no attribute 'level'
2022-09-06 12:07:18,275: Error in main loop: {ex} (sparamviewer.py:45:<module>, ERROR)
Traceback (most recent call last):
  File "C:\WorkingCopies\Github\sparameterviewer/src/sparamviewer.py", line 42, in <module>
    app = SparamviewerMainDialog(filenames)
  File "C:\WorkingCopies\Github\sparameterviewer/src\sparamviewer_main.py", line 35, in __init__
    self.logCountHandler = LogCountHandler()
  File "C:\WorkingCopies\Github\sparameterviewer/src\lib\log_counter_handler.py", line 9, in __init__
    super().__init__(self)
  File "C:\Python37\lib\logging\__init__.py", line 809, in __init__
    self.level = _checkLevel(level)
  File "C:\Python37\lib\logging\__init__.py", line 195, in _checkLevel
    raise TypeError("Level not an integer or a valid string: %r" % level)
TypeError: Level not an integer or a valid string: <LogCountHandler (WARNING)>
2022-09-06 12:09:11,971: Plotting failed: local variable 'ex' referenced before assignment (sparamviewer_main.py:759:update_plot, ERROR)
Traceback (most recent call last):
  File "C:\WorkingCopies\Github\sparameterviewer/src\sparamviewer_main.py", line 699, in update_plot
    self.show_error(f'ERROR: {ex}')
UnboundLocalError: local variable 'ex' referenced before assignment
2022-09-06 12:09:13,901: Plotting failed: local variable 'ex' referenced before assignment (sparamviewer_main.py:759:update_plot, ERROR)
Traceback (most recent call last):
  File "C:\WorkingCopies\Github\sparameterviewer/src\sparamviewer_main.py", line 699, in update_plot
    self.show_error(f'ERROR: {ex}')
UnboundLocalError: local variable 'ex' referenced before assignment
2022-09-06 12:11:09,573: Plotting failed: local variable 'ex' referenced before assignment (sparamviewer_main.py:759:update_plot, ERROR)
Traceback (most recent call last):
  File "C:\WorkingCopies\Github\sparameterviewer/src\sparamviewer_main.py", line 699, in update_plot
    self.show_error(f'ERROR: {ex}')
UnboundLocalError: local variable 'ex' referenced before assignment
2022-09-06 12:11:32,351: Plotting failed: local variable 'ex' referenced before assignment (sparamviewer_main.py:759:update_plot, ERROR)
Traceback (most recent call last):
  File "C:\WorkingCopies\Github\sparameterviewer/src\sparamviewer_main.py", line 699, in update_plot
    self.show_error(f'ERROR: {ex}')
UnboundLocalError: local variable 'ex' referenced before assignment
2022-09-06 12:11:32,359: Unable to init main dialog: local variable 'ex' referenced before assignment (sparamviewer_main.py:167:__init__, ERROR)
Traceback (most recent call last):
  File "C:\WorkingCopies\Github\sparameterviewer/src\sparamviewer_main.py", line 162, in __init__
    self.update_plot()
  File "C:\WorkingCopies\Github\sparameterviewer/src\sparamviewer_main.py", line 760, in update_plot
    raise ex
  File "C:\WorkingCopies\Github\sparameterviewer/src\sparamviewer_main.py", line 699, in update_plot
    self.show_error(f'ERROR: {ex}')
UnboundLocalError: local variable 'ex' referenced before assignment
2022-09-06 12:11:38,927: Plotting failed: local variable 'ex' referenced before assignment (sparamviewer_main.py:759:update_plot, ERROR)
Traceback (most recent call last):
  File "C:\WorkingCopies\Github\sparameterviewer/src\sparamviewer_main.py", line 699, in update_plot
    self.show_error(f'ERROR: {ex}')
UnboundLocalError: local variable 'ex' referenced before assignment
2022-09-06 12:11:39,810: Plotting failed: local variable 'ex' referenced before assignment (sparamviewer_main.py:759:update_plot, ERROR)
Traceback (most recent call last):
  File "C:\WorkingCopies\Github\sparameterviewer/src\sparamviewer_main.py", line 699, in update_plot
    self.show_error(f'ERROR: {ex}')
UnboundLocalError: local variable 'ex' referenced before assignment
2022-09-06 12:11:40,020: Plotting failed: local variable 'ex' referenced before assignment (sparamviewer_main.py:759:update_plot, ERROR)
Traceback (most recent call last):
  File "C:\WorkingCopies\Github\sparameterviewer/src\sparamviewer_main.py", line 699, in update_plot
    self.show_error(f'ERROR: {ex}')
UnboundLocalError: local variable 'ex' referenced before assignment
2022-09-06 12:11:40,179: Plotting failed: local variable 'ex' referenced before assignment (sparamviewer_main.py:759:update_plot, ERROR)
Traceback (most recent call last):
  File "C:\WorkingCopies\Github\sparameterviewer/src\sparamviewer_main.py", line 699, in update_plot
    self.show_error(f'ERROR: {ex}')
UnboundLocalError: local variable 'ex' referenced before assignment
2022-09-06 12:17:58,029: Unable to init main dialog: 'StringVar' object has no attribute 'bind' (sparamviewer_main.py:170:__init__, ERROR)
Traceback (most recent call last):
  File "C:\WorkingCopies\Github\sparameterviewer/src\sparamviewer_main.py", line 126, in __init__
    self.eval_err_msg.bind('<Button-1>', on_click_errors)
AttributeError: 'StringVar' object has no attribute 'bind'
2022-09-06 12:18:06,731: Plotting failed: 'SparamviewerMainDialog' object has no attribute 'fig' (sparamviewer_main.py:765:update_plot, ERROR)
Traceback (most recent call last):
  File "C:\WorkingCopies\Github\sparameterviewer/src\sparamviewer_main.py", line 599, in update_plot
    self.fig.clf()
AttributeError: 'SparamviewerMainDialog' object has no attribute 'fig'
2022-09-06 12:21:49,643: Plotting failed: local variable 'ex' referenced before assignment (sparamviewer_main.py:766:update_plot, ERROR)
Traceback (most recent call last):
  File "C:\WorkingCopies\Github\sparameterviewer/src\sparamviewer_main.py", line 706, in update_plot
    self.show_error(str(ex))
UnboundLocalError: local variable 'ex' referenced before assignment
2022-09-06 12:21:49,652: Unable to init main dialog: local variable 'ex' referenced before assignment (sparamviewer_main.py:171:__init__, ERROR)
Traceback (most recent call last):
  File "C:\WorkingCopies\Github\sparameterviewer/src\sparamviewer_main.py", line 166, in __init__
    self.update_plot()
  File "C:\WorkingCopies\Github\sparameterviewer/src\sparamviewer_main.py", line 767, in update_plot
    raise ex
  File "C:\WorkingCopies\Github\sparameterviewer/src\sparamviewer_main.py", line 706, in update_plot
    self.show_error(str(ex))
UnboundLocalError: local variable 'ex' referenced before assignment
2022-09-06 12:23:21,176: name 'sel_nwjs' is not defined (sparamviewer_main.py:703:update_plot, ERROR)
Traceback (most recent call last):
  File "C:\WorkingCopies\Github\sparameterviewer/src\sparamviewer_main.py", line 701, in update_plot
    ExpressionParser.eval(raw_exprs, self.files, self.get_selected_files(), add_to_plot)
  File "C:\WorkingCopies\Github\sparameterviewer/src\lib\expressions\expressions.py", line 55, in eval
    exec(code, vars_global, vars_local)
  File "<string>", line 1, in <module>
NameError: name 'sel_nwjs' is not defined
2022-09-06 12:23:28,499: name 'sel_nwjs' is not defined (sparamviewer_main.py:703:update_plot, ERROR)
Traceback (most recent call last):
  File "C:\WorkingCopies\Github\sparameterviewer/src\sparamviewer_main.py", line 701, in update_plot
    ExpressionParser.eval(raw_exprs, self.files, self.get_selected_files(), add_to_plot)
  File "C:\WorkingCopies\Github\sparameterviewer/src\lib\expressions\expressions.py", line 55, in eval
    exec(code, vars_global, vars_local)
  File "<string>", line 1, in <module>
NameError: name 'sel_nwjs' is not defined
2022-09-06 12:24:04,064: name 'sel_nwjs' is not defined (sparamviewer_main.py:703:update_plot, ERROR)
Traceback (most recent call last):
  File "C:\WorkingCopies\Github\sparameterviewer/src\sparamviewer_main.py", line 701, in update_plot
    ExpressionParser.eval(raw_exprs, self.files, self.get_selected_files(), add_to_plot)
  File "C:\WorkingCopies\Github\sparameterviewer/src\lib\expressions\expressions.py", line 55, in eval
    exec(code, vars_global, vars_local)
  File "<string>", line 1, in <module>
NameError: name 'sel_nwjs' is not defined
2022-09-06 12:25:19,700: name 'sel_nwjs' is not defined (sparamviewer_main.py:703:update_plot, ERROR)
Traceback (most recent call last):
  File "C:\WorkingCopies\Github\sparameterviewer/src\sparamviewer_main.py", line 701, in update_plot
    ExpressionParser.eval(raw_exprs, self.files, self.get_selected_files(), add_to_plot)
  File "C:\WorkingCopies\Github\sparameterviewer/src\lib\expressions\expressions.py", line 55, in eval
    exec(code, vars_global, vars_local)
  File "<string>", line 1, in <module>
NameError: name 'sel_nwjs' is not defined
2022-09-06 12:25:22,925: name 'sel_nwjs' is not defined (sparamviewer_main.py:703:update_plot, ERROR)
Traceback (most recent call last):
  File "C:\WorkingCopies\Github\sparameterviewer/src\sparamviewer_main.py", line 701, in update_plot
    ExpressionParser.eval(raw_exprs, self.files, self.get_selected_files(), add_to_plot)
  File "C:\WorkingCopies\Github\sparameterviewer/src\lib\expressions\expressions.py", line 55, in eval
    exec(code, vars_global, vars_local)
  File "<string>", line 1, in <module>
NameError: name 'sel_nwjs' is not defined
2022-09-06 12:25:35,687: name 'sel_nwjs' is not defined (sparamviewer_main.py:703:update_plot, ERROR)
Traceback (most recent call last):
  File "C:\WorkingCopies\Github\sparameterviewer/src\sparamviewer_main.py", line 701, in update_plot
    ExpressionParser.eval(raw_exprs, self.files, self.get_selected_files(), add_to_plot)
  File "C:\WorkingCopies\Github\sparameterviewer/src\lib\expressions\expressions.py", line 55, in eval
    exec(code, vars_global, vars_local)
  File "<string>", line 1, in <module>
NameError: name 'sel_nwjs' is not defined
2022-09-06 12:28:06,436: invalid syntax (<string>, line 1) (sparamviewer_main.py:706:update_plot, ERROR)
Traceback (most recent call last):
  File "C:\WorkingCopies\Github\sparameterviewer/src\sparamviewer_main.py", line 704, in update_plot
    ExpressionParser.eval(raw_exprs, self.files, self.get_selected_files(), add_to_plot)
  File "C:\WorkingCopies\Github\sparameterviewer/src\lib\expressions\expressions.py", line 55, in eval
    exec(code, vars_global, vars_local)
  File "<string>", line 1
    sel _nws().s().plot()
           ^
SyntaxError: invalid syntax
2022-09-06 12:28:15,718: name 'ggg' is not defined (sparamviewer_main.py:706:update_plot, ERROR)
Traceback (most recent call last):
  File "C:\WorkingCopies\Github\sparameterviewer/src\sparamviewer_main.py", line 704, in update_plot
    ExpressionParser.eval(raw_exprs, self.files, self.get_selected_files(), add_to_plot)
  File "C:\WorkingCopies\Github\sparameterviewer/src\lib\expressions\expressions.py", line 55, in eval
    exec(code, vars_global, vars_local)
  File "<string>", line 1, in <module>
NameError: name 'ggg' is not defined
2022-09-07 13:49:03,105: name 'ggg' is not defined (sparamviewer_main.py:706:update_plot, ERROR)
Traceback (most recent call last):
  File "C:\WorkingCopies\Github\sparameterviewer\src\sparamviewer_main.py", line 704, in update_plot
    ExpressionParser.eval(raw_exprs, self.files, self.get_selected_files(), add_to_plot)
  File "C:\WorkingCopies\Github\sparameterviewer\src\lib\expressions\expressions.py", line 55, in eval
    exec(code, vars_global, vars_local)
  File "<string>", line 1, in <module>
NameError: name 'ggg' is not defined
2022-09-07 13:49:03,583: name 'ggg' is not defined (sparamviewer_main.py:706:update_plot, ERROR)
Traceback (most recent call last):
  File "C:\WorkingCopies\Github\sparameterviewer\src\sparamviewer_main.py", line 704, in update_plot
    ExpressionParser.eval(raw_exprs, self.files, self.get_selected_files(), add_to_plot)
  File "C:\WorkingCopies\Github\sparameterviewer\src\lib\expressions\expressions.py", line 55, in eval
    exec(code, vars_global, vars_local)
  File "<string>", line 1, in <module>
NameError: name 'ggg' is not defined
2022-09-08 08:48:03,680: Argument has dimension 2, but must nave 1 or 71 (sparamviewer_main.py:706:update_plot, ERROR)
Traceback (most recent call last):
  File "C:\WorkingCopies\Github\sparameterviewer\src\sparamviewer_main.py", line 704, in update_plot
    ExpressionParser.eval(raw_exprs, self.files, self.get_selected_files(), add_to_plot)
  File "C:\WorkingCopies\Github\sparameterviewer\src\lib\expressions\expressions.py", line 55, in eval
    exec(code, vars_global, vars_local)
  File "<string>", line 1, in <module>
  File "C:\WorkingCopies\Github\sparameterviewer\src\lib\expressions\sparams.py", line 182, in __truediv__
    return self._binary_op(SParam.__truediv__, others, True)
  File "C:\WorkingCopies\Github\sparameterviewer\src\lib\expressions\sparams.py", line 170, in _binary_op
    for sp,other in zip(self.sps, self._broadcast(others)):
  File "C:\WorkingCopies\Github\sparameterviewer\src\lib\expressions\sparams.py", line 152, in _broadcast
    raise ValueError(f'Argument has dimension {len(sp.sps)}, but must nave 1 or {len(self.sps)}')
ValueError: Argument has dimension 2, but must nave 1 or 71
2022-09-14 09:42:32,108: Unable to init main dialog: 'SParamViewerAppSettings' object has no attribute 'lock_xaxis' (sparamviewer_main.py:172:__init__, ERROR)
Traceback (most recent call last):
  File "C:\WorkingCopies\Github\sparameterviewer/src\sparamviewer_main.py", line 67, in __init__
    self.lock_plot_xaxis.set('1' if self.settings.lock_xaxis else '0')
AttributeError: 'SParamViewerAppSettings' object has no attribute 'lock_xaxis'
2022-09-14 09:42:43,509: Plotting failed: 'SparamviewerMainDialog' object has no attribute 'fig' (sparamviewer_main.py:775:update_plot, ERROR)
Traceback (most recent call last):
  File "C:\WorkingCopies\Github\sparameterviewer/src\sparamviewer_main.py", line 602, in update_plot
    self.fig.clf()
AttributeError: 'SparamviewerMainDialog' object has no attribute 'fig'
2022-09-14 09:42:47,297: Plotting failed: 'SparamviewerMainDialog' object has no attribute 'fig' (sparamviewer_main.py:775:update_plot, ERROR)
Traceback (most recent call last):
  File "C:\WorkingCopies\Github\sparameterviewer/src\sparamviewer_main.py", line 602, in update_plot
    self.fig.clf()
AttributeError: 'SparamviewerMainDialog' object has no attribute 'fig'
2022-09-14 09:43:43,213: Unable to init main dialog: 'SParamViewerAppSettings' object has no attribute 'lock_xaxis' (sparamviewer_main.py:172:__init__, ERROR)
Traceback (most recent call last):
  File "C:\WorkingCopies\Github\sparameterviewer/src\sparamviewer_main.py", line 67, in __init__
    self.lock_plot_xaxis.set('1' if self.settings.lock_xaxis else '0')
AttributeError: 'SParamViewerAppSettings' object has no attribute 'lock_xaxis'
2022-09-14 09:43:46,894: Plotting failed: 'SparamviewerMainDialog' object has no attribute 'fig' (sparamviewer_main.py:775:update_plot, ERROR)
Traceback (most recent call last):
  File "C:\WorkingCopies\Github\sparameterviewer/src\sparamviewer_main.py", line 602, in update_plot
    self.fig.clf()
AttributeError: 'SparamviewerMainDialog' object has no attribute 'fig'
2022-09-14 09:43:47,909: Plotting failed: 'SparamviewerMainDialog' object has no attribute 'fig' (sparamviewer_main.py:775:update_plot, ERROR)
Traceback (most recent call last):
  File "C:\WorkingCopies\Github\sparameterviewer/src\sparamviewer_main.py", line 602, in update_plot
    self.fig.clf()
AttributeError: 'SparamviewerMainDialog' object has no attribute 'fig'
2022-09-14 09:44:14,096: Unable to init main dialog: 'SParamViewerAppSettings' object has no attribute 'lock_xaxis' (sparamviewer_main.py:172:__init__, ERROR)
Traceback (most recent call last):
  File "C:\WorkingCopies\Github\sparameterviewer/src\sparamviewer_main.py", line 67, in __init__
    self.lock_plot_xaxis.set('1' if self.settings.lock_xaxis else '0')
AttributeError: 'SParamViewerAppSettings' object has no attribute 'lock_xaxis'
2022-09-14 09:48:10,681: Unable to init main dialog: 'SparamviewerMainDialog' object has no attribute 'show_single_legend' (sparamviewer_main.py:172:__init__, ERROR)
Traceback (most recent call last):
  File "C:\WorkingCopies\Github\sparameterviewer/src\sparamviewer_main.py", line 66, in __init__
    self.show_single_legend.set('1' if self.settings.always_show_names else '0')
AttributeError: 'SparamviewerMainDialog' object has no attribute 'show_single_legend'
2022-09-14 09:49:21,622: Unable to init main dialog: 'SparamviewerMainDialog' object has no attribute 'show_single_legend' (sparamviewer_main.py:172:__init__, ERROR)
Traceback (most recent call last):
  File "C:\WorkingCopies\Github\sparameterviewer/src\sparamviewer_main.py", line 66, in __init__
    self.show_single_legend.set('1' if self.settings.always_show_names else '0')
AttributeError: 'SparamviewerMainDialog' object has no attribute 'show_single_legend'
2022-09-14 09:50:50,075: Unable to init main dialog: 'SparamviewerMainDialog' object has no attribute 'show_single_legend' (sparamviewer_main.py:172:__init__, ERROR)
Traceback (most recent call last):
  File "C:\WorkingCopies\Github\sparameterviewer/src\sparamviewer_main.py", line 66, in __init__
    self.show_single_legend.set('1' if self.settings.always_show_names else '0')
AttributeError: 'SparamviewerMainDialog' object has no attribute 'show_single_legend'
2022-09-14 10:20:27,397: Plotting failed: bad character range _-/ at position 2 (sparamviewer_main.py:775:update_plot, ERROR)
Traceback (most recent call last):
  File "C:\WorkingCopies\Github\sparameterviewer/src\sparamviewer_main.py", line 750, in update_plot
    self.plot.render()
  File "C:\WorkingCopies\Github\sparameterviewer/src\lib\plot.py", line 186, in render
    labels = shorten_labels(labels)
  File "C:\WorkingCopies\Github\sparameterviewer/src\lib\plot.py", line 183, in shorten_labels
    split('Hello Andy')
  File "C:\WorkingCopies\Github\sparameterviewer/src\lib\plot.py", line 180, in split
    m = re.search(r'[ _-/\\+~*#.,]', s)
  File "C:\Python37\lib\re.py", line 183, in search
    return _compile(pattern, flags).search(string)
  File "C:\Python37\lib\re.py", line 286, in _compile
    p = sre_compile.compile(pattern, flags)
  File "C:\Python37\lib\sre_compile.py", line 764, in compile
    p = sre_parse.parse(p, flags)
  File "C:\Python37\lib\sre_parse.py", line 924, in parse
    p = _parse_sub(source, pattern, flags & SRE_FLAG_VERBOSE, 0)
  File "C:\Python37\lib\sre_parse.py", line 420, in _parse_sub
    not nested and not items))
  File "C:\Python37\lib\sre_parse.py", line 574, in _parse
    raise source.error(msg, len(this) + 1 + len(that))
re.error: bad character range _-/ at position 2
2022-09-16 11:30:47,439: name 'Stim' is not defined (sparamviewer_main.py:716:update_plot, ERROR)
Traceback (most recent call last):
  File "C:\WorkingCopies\Github\sparameterviewer\src\sparamviewer_main.py", line 714, in update_plot
    ExpressionParser.eval(raw_exprs, self.files, self.get_selected_files(), add_to_plot)
  File "C:\WorkingCopies\Github\sparameterviewer\src\lib\expressions\expressions.py", line 55, in eval
    exec(code, vars_global, vars_local)
  File "<string>", line 7, in <module>
NameError: name 'Stim' is not defined
2022-09-19 12:46:21,857: name 'Stim' is not defined (sparamviewer_main.py:716:update_plot, ERROR)
Traceback (most recent call last):
  File "C:\WorkingCopies\Github\sparameterviewer\src\sparamviewer_main.py", line 714, in update_plot
    ExpressionParser.eval(raw_exprs, self.files, self.get_selected_files(), add_to_plot)
  File "C:\WorkingCopies\Github\sparameterviewer\src\lib\expressions\expressions.py", line 55, in eval
    exec(code, vars_global, vars_local)
  File "<string>", line 6, in <module>
NameError: name 'Stim' is not defined
2022-09-19 12:48:02,327: name 'STIM5' is not defined (sparamviewer_main.py:716:update_plot, ERROR)
Traceback (most recent call last):
  File "C:\WorkingCopies\Github\sparameterviewer\src\sparamviewer_main.py", line 714, in update_plot
    ExpressionParser.eval(raw_exprs, self.files, self.get_selected_files(), add_to_plot)
  File "C:\WorkingCopies\Github\sparameterviewer\src\lib\expressions\expressions.py", line 55, in eval
    exec(code, vars_global, vars_local)
  File "<string>", line 10, in <module>
NameError: name 'STIM5' is not defined
2022-11-04 15:38:52,516: db() takes 1 positional argument but 2 were given (sparamviewer_main.py:716:update_plot, ERROR)
Traceback (most recent call last):
  File "C:\WorkingCopies\Github\sparameterviewer\src\sparamviewer_main.py", line 714, in update_plot
    ExpressionParser.eval(raw_exprs, self.files, self.get_selected_files(), add_to_plot)
  File "C:\WorkingCopies\Github\sparameterviewer\src\lib\expressions\expressions.py", line 55, in eval
    exec(code, vars_global, vars_local)
  File "<string>", line 2, in <module>
TypeError: db() takes 1 positional argument but 2 were given
2022-11-04 15:40:07,586: invalid syntax (<string>, line 2) (sparamviewer_main.py:716:update_plot, ERROR)
Traceback (most recent call last):
  File "C:\WorkingCopies\Github\sparameterviewer\src\sparamviewer_main.py", line 714, in update_plot
    ExpressionParser.eval(raw_exprs, self.files, self.get_selected_files(), add_to_plot)
  File "C:\WorkingCopies\Github\sparameterviewer\src\lib\expressions\expressions.py", line 55, in eval
    exec(code, vars_global, vars_local)
  File "<string>", line 2
    (sel_nws().s(2,1)db()).plot()
                      ^
SyntaxError: invalid syntax
2022-11-16 16:09:37,115: The pattern "*_Uncal_*" matched 0 networks, but need exactly one (sparamviewer_main.py:716:update_plot, ERROR)
Traceback (most recent call last):
  File "C:\WorkingCopies\Github\sparameterviewer/src\sparamviewer_main.py", line 714, in update_plot
    ExpressionParser.eval(raw_exprs, self.files, self.get_selected_files(), add_to_plot)
  File "C:\WorkingCopies\Github\sparameterviewer/src\lib\expressions\expressions.py", line 55, in eval
    exec(code, vars_global, vars_local)
  File "<string>", line 2, in <module>
  File "C:\WorkingCopies\Github\sparameterviewer/src\lib\expressions\expressions.py", line 42, in nw
    return select_networks(available_networks, pattern, single=True)
  File "C:\WorkingCopies\Github\sparameterviewer/src\lib\expressions\expressions.py", line 32, in select_networks
    raise RuntimeError(f'The pattern "{pattern}" matched {len(nws)} networks, but need exactly one')
RuntimeError: The pattern "*_Uncal_*" matched 0 networks, but need exactly one
2022-11-16 16:09:43,008: The pattern "*_Uncal_*" matched 0 networks, but need exactly one (sparamviewer_main.py:716:update_plot, ERROR)
Traceback (most recent call last):
  File "C:\WorkingCopies\Github\sparameterviewer/src\sparamviewer_main.py", line 714, in update_plot
    ExpressionParser.eval(raw_exprs, self.files, self.get_selected_files(), add_to_plot)
  File "C:\WorkingCopies\Github\sparameterviewer/src\lib\expressions\expressions.py", line 55, in eval
    exec(code, vars_global, vars_local)
  File "<string>", line 2, in <module>
  File "C:\WorkingCopies\Github\sparameterviewer/src\lib\expressions\expressions.py", line 42, in nw
    return select_networks(available_networks, pattern, single=True)
  File "C:\WorkingCopies\Github\sparameterviewer/src\lib\expressions\expressions.py", line 32, in select_networks
    raise RuntimeError(f'The pattern "{pattern}" matched {len(nws)} networks, but need exactly one')
RuntimeError: The pattern "*_Uncal_*" matched 0 networks, but need exactly one
2022-11-16 16:10:55,539: The pattern "*_Uncal_*" matched 0 networks, but need exactly one (sparamviewer_main.py:716:update_plot, ERROR)
Traceback (most recent call last):
  File "C:\WorkingCopies\Github\sparameterviewer/src\sparamviewer_main.py", line 714, in update_plot
    ExpressionParser.eval(raw_exprs, self.files, self.get_selected_files(), add_to_plot)
  File "C:\WorkingCopies\Github\sparameterviewer/src\lib\expressions\expressions.py", line 55, in eval
    exec(code, vars_global, vars_local)
  File "<string>", line 2, in <module>
  File "C:\WorkingCopies\Github\sparameterviewer/src\lib\expressions\expressions.py", line 42, in nw
    return select_networks(available_networks, pattern, single=True)
  File "C:\WorkingCopies\Github\sparameterviewer/src\lib\expressions\expressions.py", line 32, in select_networks
    raise RuntimeError(f'The pattern "{pattern}" matched {len(nws)} networks, but need exactly one')
RuntimeError: The pattern "*_Uncal_*" matched 0 networks, but need exactly one
2022-11-16 16:11:09,068: The pattern "*_Uncal_*" matched 0 networks, but need exactly one (sparamviewer_main.py:716:update_plot, ERROR)
Traceback (most recent call last):
  File "C:\WorkingCopies\Github\sparameterviewer/src\sparamviewer_main.py", line 714, in update_plot
    ExpressionParser.eval(raw_exprs, self.files, self.get_selected_files(), add_to_plot)
  File "C:\WorkingCopies\Github\sparameterviewer/src\lib\expressions\expressions.py", line 55, in eval
    exec(code, vars_global, vars_local)
  File "<string>", line 2, in <module>
  File "C:\WorkingCopies\Github\sparameterviewer/src\lib\expressions\expressions.py", line 42, in nw
    return select_networks(available_networks, pattern, single=True)
  File "C:\WorkingCopies\Github\sparameterviewer/src\lib\expressions\expressions.py", line 32, in select_networks
    raise RuntimeError(f'The pattern "{pattern}" matched {len(nws)} networks, but need exactly one')
RuntimeError: The pattern "*_Uncal_*" matched 0 networks, but need exactly one
2022-11-16 16:11:36,552: The pattern "*_Uncal_*" matched 0 networks, but need exactly one (sparamviewer_main.py:716:update_plot, ERROR)
Traceback (most recent call last):
  File "C:\WorkingCopies\Github\sparameterviewer/src\sparamviewer_main.py", line 714, in update_plot
    ExpressionParser.eval(raw_exprs, self.files, self.get_selected_files(), add_to_plot)
  File "C:\WorkingCopies\Github\sparameterviewer/src\lib\expressions\expressions.py", line 55, in eval
    exec(code, vars_global, vars_local)
  File "<string>", line 2, in <module>
  File "C:\WorkingCopies\Github\sparameterviewer/src\lib\expressions\expressions.py", line 42, in nw
    return select_networks(available_networks, pattern, single=True)
  File "C:\WorkingCopies\Github\sparameterviewer/src\lib\expressions\expressions.py", line 32, in select_networks
    raise RuntimeError(f'The pattern "{pattern}" matched {len(nws)} networks, but need exactly one')
RuntimeError: The pattern "*_Uncal_*" matched 0 networks, but need exactly one
2022-11-16 16:19:11,710: The pattern "*_Uncal_*" matched 0 networks, but need exactly one (sparamviewer_main.py:720:update_plot, ERROR)
Traceback (most recent call last):
  File "C:\WorkingCopies\Github\sparameterviewer/src\sparamviewer_main.py", line 718, in update_plot
    ExpressionParser.eval(raw_exprs, self.files, self.get_selected_files(), add_to_plot)
  File "C:\WorkingCopies\Github\sparameterviewer/src\lib\expressions\expressions.py", line 55, in eval
    exec(code, vars_global, vars_local)
  File "<string>", line 2, in <module>
  File "C:\WorkingCopies\Github\sparameterviewer/src\lib\expressions\expressions.py", line 42, in nw
    return select_networks(available_networks, pattern, single=True)
  File "C:\WorkingCopies\Github\sparameterviewer/src\lib\expressions\expressions.py", line 32, in select_networks
    raise RuntimeError(f'The pattern "{pattern}" matched {len(nws)} networks, but need exactly one')
RuntimeError: The pattern "*_Uncal_*" matched 0 networks, but need exactly one
2022-11-16 16:21:36,814: The pattern "*_Uncal_*" matched 0 networks, but need exactly one (sparamviewer_main.py:720:update_plot, ERROR)
Traceback (most recent call last):
  File "C:\WorkingCopies\Github\sparameterviewer/src\sparamviewer_main.py", line 718, in update_plot
    ExpressionParser.eval(raw_exprs, self.files, self.get_selected_files(), add_to_plot)
  File "C:\WorkingCopies\Github\sparameterviewer/src\lib\expressions\expressions.py", line 55, in eval
    exec(code, vars_global, vars_local)
  File "<string>", line 2, in <module>
  File "C:\WorkingCopies\Github\sparameterviewer/src\lib\expressions\expressions.py", line 42, in nw
    return select_networks(available_networks, pattern, single=True)
  File "C:\WorkingCopies\Github\sparameterviewer/src\lib\expressions\expressions.py", line 32, in select_networks
    raise RuntimeError(f'The pattern "{pattern}" matched {len(nws)} networks, but need exactly one')
RuntimeError: The pattern "*_Uncal_*" matched 0 networks, but need exactly one
2022-11-16 16:32:43,855: The pattern "*_Uncal_*" matched 0 networks, but need exactly one (sparamviewer_main.py:730:update_plot, ERROR)
Traceback (most recent call last):
  File "C:\WorkingCopies\Github\sparameterviewer/src\sparamviewer_main.py", line 728, in update_plot
    ExpressionParser.eval(raw_exprs, self.files, self.get_selected_files(), add_to_plot)
  File "C:\WorkingCopies\Github\sparameterviewer/src\lib\expressions\expressions.py", line 55, in eval
    exec(code, vars_global, vars_local)
  File "<string>", line 2, in <module>
  File "C:\WorkingCopies\Github\sparameterviewer/src\lib\expressions\expressions.py", line 42, in nw
    return select_networks(available_networks, pattern, single=True)
  File "C:\WorkingCopies\Github\sparameterviewer/src\lib\expressions\expressions.py", line 32, in select_networks
    raise RuntimeError(f'The pattern "{pattern}" matched {len(nws)} networks, but need exactly one')
RuntimeError: The pattern "*_Uncal_*" matched 0 networks, but need exactly one
2022-11-16 16:32:47,345: The pattern "*_Uncal_*" matched 0 networks, but need exactly one (sparamviewer_main.py:730:update_plot, ERROR)
Traceback (most recent call last):
  File "C:\WorkingCopies\Github\sparameterviewer/src\sparamviewer_main.py", line 728, in update_plot
    ExpressionParser.eval(raw_exprs, self.files, self.get_selected_files(), add_to_plot)
  File "C:\WorkingCopies\Github\sparameterviewer/src\lib\expressions\expressions.py", line 55, in eval
    exec(code, vars_global, vars_local)
  File "<string>", line 2, in <module>
  File "C:\WorkingCopies\Github\sparameterviewer/src\lib\expressions\expressions.py", line 42, in nw
    return select_networks(available_networks, pattern, single=True)
  File "C:\WorkingCopies\Github\sparameterviewer/src\lib\expressions\expressions.py", line 32, in select_networks
    raise RuntimeError(f'The pattern "{pattern}" matched {len(nws)} networks, but need exactly one')
RuntimeError: The pattern "*_Uncal_*" matched 0 networks, but need exactly one
2022-11-16 16:32:56,859: Exporting failed: 'AxesSubplot' object has no attribute 'savefig' (sparamviewer_main.py:522:on_export, ERROR)
Traceback (most recent call last):
  File "C:\WorkingCopies\Github\sparameterviewer/src\sparamviewer_main.py", line 518, in on_export
    self.plot.plot.savefig(filename)
AttributeError: 'AxesSubplot' object has no attribute 'savefig'
2022-12-22 08:06:14,049: Unable to init main dialog: _load_all_files_in_dir() takes 1 positional argument but 2 were given (sparamviewer_main.py:175:__init__, ERROR)
Traceback (most recent call last):
  File "C:\WorkingCopies\Github\sparameterviewer/src\sparamviewer_main.py", line 169, in __init__
    self.load_files(filenames)
  File "C:\WorkingCopies\Github\sparameterviewer/src\sparamviewer_main.py", line 609, in load_files
    self._load_all_files_in_dir(dir)
TypeError: _load_all_files_in_dir() takes 1 positional argument but 2 were given
2022-12-22 08:06:44,868: Unable to init main dialog: 'str' object has no attribute 'file_path' (sparamviewer_main.py:175:__init__, ERROR)
Traceback (most recent call last):
  File "C:\WorkingCopies\Github\sparameterviewer/src\sparamviewer_main.py", line 169, in __init__
    self.load_files(filenames)
  File "C:\WorkingCopies\Github\sparameterviewer/src\sparamviewer_main.py", line 610, in load_files
    self.update_file_list(selected_filenames=filenames)
  File "C:\WorkingCopies\Github\sparameterviewer/src\sparamviewer_main.py", line 638, in update_file_list
    elif os.path.abspath(file.file_path) in [os.path.abspath(f.file_path) for f in selected_filenames]:
  File "C:\WorkingCopies\Github\sparameterviewer/src\sparamviewer_main.py", line 638, in <listcomp>
    elif os.path.abspath(file.file_path) in [os.path.abspath(f.file_path) for f in selected_filenames]:
AttributeError: 'str' object has no attribute 'file_path'
2022-12-22 08:57:09,189: local variable 'touched_files' referenced before assignment (sparamviewer_main.py:807:update_plot, ERROR)
Traceback (most recent call last):
  File "C:\WorkingCopies\Github\sparameterviewer/src\sparamviewer_main.py", line 805, in update_plot
    touched_files = ExpressionParser.eval(raw_exprs, self.files, selected_files, add_to_plot)
  File "C:\WorkingCopies\Github\sparameterviewer/src\lib\expressions\expressions.py", line 67, in eval
    exec(code, vars_global, vars_local)
  File "<string>", line 1, in <module>
  File "C:\WorkingCopies\Github\sparameterviewer/src\lib\expressions\expressions.py", line 47, in nws
    nws = select_networks(available_networks, pattern, single=False)
  File "C:\WorkingCopies\Github\sparameterviewer/src\lib\expressions\expressions.py", line 35, in select_networks
    touch_files(nws)
  File "C:\WorkingCopies\Github\sparameterviewer/src\lib\expressions\expressions.py", line 39, in touch_files
    touched_files = list(set(touched_files.extend(files)))
UnboundLocalError: local variable 'touched_files' referenced before assignment
2022-12-22 08:57:09,858: local variable 'touched_files' referenced before assignment (sparamviewer_main.py:807:update_plot, ERROR)
Traceback (most recent call last):
  File "C:\WorkingCopies\Github\sparameterviewer/src\sparamviewer_main.py", line 805, in update_plot
    touched_files = ExpressionParser.eval(raw_exprs, self.files, selected_files, add_to_plot)
  File "C:\WorkingCopies\Github\sparameterviewer/src\lib\expressions\expressions.py", line 67, in eval
    exec(code, vars_global, vars_local)
  File "<string>", line 1, in <module>
  File "C:\WorkingCopies\Github\sparameterviewer/src\lib\expressions\expressions.py", line 47, in nws
    nws = select_networks(available_networks, pattern, single=False)
  File "C:\WorkingCopies\Github\sparameterviewer/src\lib\expressions\expressions.py", line 35, in select_networks
    touch_files(nws)
  File "C:\WorkingCopies\Github\sparameterviewer/src\lib\expressions\expressions.py", line 39, in touch_files
    touched_files = list(set(touched_files.extend(files)))
UnboundLocalError: local variable 'touched_files' referenced before assignment
2022-12-22 08:57:12,999: local variable 'touched_files' referenced before assignment (sparamviewer_main.py:807:update_plot, ERROR)
Traceback (most recent call last):
  File "C:\WorkingCopies\Github\sparameterviewer/src\sparamviewer_main.py", line 805, in update_plot
    touched_files = ExpressionParser.eval(raw_exprs, self.files, selected_files, add_to_plot)
  File "C:\WorkingCopies\Github\sparameterviewer/src\lib\expressions\expressions.py", line 67, in eval
    exec(code, vars_global, vars_local)
  File "<string>", line 1, in <module>
  File "C:\WorkingCopies\Github\sparameterviewer/src\lib\expressions\expressions.py", line 47, in nws
    nws = select_networks(available_networks, pattern, single=False)
  File "C:\WorkingCopies\Github\sparameterviewer/src\lib\expressions\expressions.py", line 35, in select_networks
    touch_files(nws)
  File "C:\WorkingCopies\Github\sparameterviewer/src\lib\expressions\expressions.py", line 39, in touch_files
    touched_files = list(set(touched_files.extend(files)))
UnboundLocalError: local variable 'touched_files' referenced before assignment
2022-12-22 08:57:13,733: local variable 'touched_files' referenced before assignment (sparamviewer_main.py:807:update_plot, ERROR)
Traceback (most recent call last):
  File "C:\WorkingCopies\Github\sparameterviewer/src\sparamviewer_main.py", line 805, in update_plot
    touched_files = ExpressionParser.eval(raw_exprs, self.files, selected_files, add_to_plot)
  File "C:\WorkingCopies\Github\sparameterviewer/src\lib\expressions\expressions.py", line 67, in eval
    exec(code, vars_global, vars_local)
  File "<string>", line 1, in <module>
  File "C:\WorkingCopies\Github\sparameterviewer/src\lib\expressions\expressions.py", line 47, in nws
    nws = select_networks(available_networks, pattern, single=False)
  File "C:\WorkingCopies\Github\sparameterviewer/src\lib\expressions\expressions.py", line 35, in select_networks
    touch_files(nws)
  File "C:\WorkingCopies\Github\sparameterviewer/src\lib\expressions\expressions.py", line 39, in touch_files
    touched_files = list(set(touched_files.extend(files)))
UnboundLocalError: local variable 'touched_files' referenced before assignment
2022-12-22 08:57:44,892: 'NoneType' object is not iterable (sparamviewer_main.py:807:update_plot, ERROR)
Traceback (most recent call last):
  File "C:\WorkingCopies\Github\sparameterviewer/src\sparamviewer_main.py", line 805, in update_plot
    touched_files = ExpressionParser.eval(raw_exprs, self.files, selected_files, add_to_plot)
  File "C:\WorkingCopies\Github\sparameterviewer/src\lib\expressions\expressions.py", line 68, in eval
    exec(code, vars_global, vars_local)
  File "<string>", line 1, in <module>
  File "C:\WorkingCopies\Github\sparameterviewer/src\lib\expressions\expressions.py", line 48, in nws
    nws = select_networks(available_networks, pattern, single=False)
  File "C:\WorkingCopies\Github\sparameterviewer/src\lib\expressions\expressions.py", line 39, in select_networks
    touch_files(nws)
  File "C:\WorkingCopies\Github\sparameterviewer/src\lib\expressions\expressions.py", line 26, in touch_files
    touched_files = list(set(touched_files.extend(files)))
TypeError: 'NoneType' object is not iterable
2022-12-22 08:57:45,262: 'NoneType' object is not iterable (sparamviewer_main.py:807:update_plot, ERROR)
Traceback (most recent call last):
  File "C:\WorkingCopies\Github\sparameterviewer/src\sparamviewer_main.py", line 805, in update_plot
    touched_files = ExpressionParser.eval(raw_exprs, self.files, selected_files, add_to_plot)
  File "C:\WorkingCopies\Github\sparameterviewer/src\lib\expressions\expressions.py", line 68, in eval
    exec(code, vars_global, vars_local)
  File "<string>", line 1, in <module>
  File "C:\WorkingCopies\Github\sparameterviewer/src\lib\expressions\expressions.py", line 48, in nws
    nws = select_networks(available_networks, pattern, single=False)
  File "C:\WorkingCopies\Github\sparameterviewer/src\lib\expressions\expressions.py", line 39, in select_networks
    touch_files(nws)
  File "C:\WorkingCopies\Github\sparameterviewer/src\lib\expressions\expressions.py", line 26, in touch_files
    touched_files = list(set(touched_files.extend(files)))
TypeError: 'NoneType' object is not iterable
2022-12-22 08:57:53,625: 'NoneType' object is not iterable (sparamviewer_main.py:807:update_plot, ERROR)
Traceback (most recent call last):
  File "C:\WorkingCopies\Github\sparameterviewer/src\sparamviewer_main.py", line 805, in update_plot
    touched_files = ExpressionParser.eval(raw_exprs, self.files, selected_files, add_to_plot)
  File "C:\WorkingCopies\Github\sparameterviewer/src\lib\expressions\expressions.py", line 68, in eval
    exec(code, vars_global, vars_local)
  File "<string>", line 1, in <module>
  File "C:\WorkingCopies\Github\sparameterviewer/src\lib\expressions\expressions.py", line 48, in nws
    nws = select_networks(available_networks, pattern, single=False)
  File "C:\WorkingCopies\Github\sparameterviewer/src\lib\expressions\expressions.py", line 39, in select_networks
    touch_files(nws)
  File "C:\WorkingCopies\Github\sparameterviewer/src\lib\expressions\expressions.py", line 26, in touch_files
    touched_files = list(set(touched_files.extend(files)))
TypeError: 'NoneType' object is not iterable
2022-12-22 08:57:54,791: 'NoneType' object is not iterable (sparamviewer_main.py:807:update_plot, ERROR)
Traceback (most recent call last):
  File "C:\WorkingCopies\Github\sparameterviewer/src\sparamviewer_main.py", line 805, in update_plot
    touched_files = ExpressionParser.eval(raw_exprs, self.files, selected_files, add_to_plot)
  File "C:\WorkingCopies\Github\sparameterviewer/src\lib\expressions\expressions.py", line 68, in eval
    exec(code, vars_global, vars_local)
  File "<string>", line 1, in <module>
  File "C:\WorkingCopies\Github\sparameterviewer/src\lib\expressions\expressions.py", line 48, in nws
    nws = select_networks(available_networks, pattern, single=False)
  File "C:\WorkingCopies\Github\sparameterviewer/src\lib\expressions\expressions.py", line 39, in select_networks
    touch_files(nws)
  File "C:\WorkingCopies\Github\sparameterviewer/src\lib\expressions\expressions.py", line 26, in touch_files
    touched_files = list(set(touched_files.extend(files)))
TypeError: 'NoneType' object is not iterable
2022-12-22 08:57:55,477: 'NoneType' object is not iterable (sparamviewer_main.py:807:update_plot, ERROR)
Traceback (most recent call last):
  File "C:\WorkingCopies\Github\sparameterviewer/src\sparamviewer_main.py", line 805, in update_plot
    touched_files = ExpressionParser.eval(raw_exprs, self.files, selected_files, add_to_plot)
  File "C:\WorkingCopies\Github\sparameterviewer/src\lib\expressions\expressions.py", line 68, in eval
    exec(code, vars_global, vars_local)
  File "<string>", line 1, in <module>
  File "C:\WorkingCopies\Github\sparameterviewer/src\lib\expressions\expressions.py", line 48, in nws
    nws = select_networks(available_networks, pattern, single=False)
  File "C:\WorkingCopies\Github\sparameterviewer/src\lib\expressions\expressions.py", line 39, in select_networks
    touch_files(nws)
  File "C:\WorkingCopies\Github\sparameterviewer/src\lib\expressions\expressions.py", line 26, in touch_files
    touched_files = list(set(touched_files.extend(files)))
TypeError: 'NoneType' object is not iterable
2022-12-22 08:57:55,823: 'NoneType' object is not iterable (sparamviewer_main.py:807:update_plot, ERROR)
Traceback (most recent call last):
  File "C:\WorkingCopies\Github\sparameterviewer/src\sparamviewer_main.py", line 805, in update_plot
    touched_files = ExpressionParser.eval(raw_exprs, self.files, selected_files, add_to_plot)
  File "C:\WorkingCopies\Github\sparameterviewer/src\lib\expressions\expressions.py", line 68, in eval
    exec(code, vars_global, vars_local)
  File "<string>", line 1, in <module>
  File "C:\WorkingCopies\Github\sparameterviewer/src\lib\expressions\expressions.py", line 48, in nws
    nws = select_networks(available_networks, pattern, single=False)
  File "C:\WorkingCopies\Github\sparameterviewer/src\lib\expressions\expressions.py", line 39, in select_networks
    touch_files(nws)
  File "C:\WorkingCopies\Github\sparameterviewer/src\lib\expressions\expressions.py", line 26, in touch_files
    touched_files = list(set(touched_files.extend(files)))
TypeError: 'NoneType' object is not iterable
2022-12-22 08:57:58,492: 'NoneType' object is not iterable (sparamviewer_main.py:807:update_plot, ERROR)
Traceback (most recent call last):
  File "C:\WorkingCopies\Github\sparameterviewer/src\sparamviewer_main.py", line 805, in update_plot
    touched_files = ExpressionParser.eval(raw_exprs, self.files, selected_files, add_to_plot)
  File "C:\WorkingCopies\Github\sparameterviewer/src\lib\expressions\expressions.py", line 68, in eval
    exec(code, vars_global, vars_local)
  File "<string>", line 1, in <module>
  File "C:\WorkingCopies\Github\sparameterviewer/src\lib\expressions\expressions.py", line 48, in nws
    nws = select_networks(available_networks, pattern, single=False)
  File "C:\WorkingCopies\Github\sparameterviewer/src\lib\expressions\expressions.py", line 39, in select_networks
    touch_files(nws)
  File "C:\WorkingCopies\Github\sparameterviewer/src\lib\expressions\expressions.py", line 26, in touch_files
    touched_files = list(set(touched_files.extend(files)))
TypeError: 'NoneType' object is not iterable
2022-12-22 08:57:58,993: 'NoneType' object is not iterable (sparamviewer_main.py:807:update_plot, ERROR)
Traceback (most recent call last):
  File "C:\WorkingCopies\Github\sparameterviewer/src\sparamviewer_main.py", line 805, in update_plot
    touched_files = ExpressionParser.eval(raw_exprs, self.files, selected_files, add_to_plot)
  File "C:\WorkingCopies\Github\sparameterviewer/src\lib\expressions\expressions.py", line 68, in eval
    exec(code, vars_global, vars_local)
  File "<string>", line 1, in <module>
  File "C:\WorkingCopies\Github\sparameterviewer/src\lib\expressions\expressions.py", line 48, in nws
    nws = select_networks(available_networks, pattern, single=False)
  File "C:\WorkingCopies\Github\sparameterviewer/src\lib\expressions\expressions.py", line 39, in select_networks
    touch_files(nws)
  File "C:\WorkingCopies\Github\sparameterviewer/src\lib\expressions\expressions.py", line 26, in touch_files
    touched_files = list(set(touched_files.extend(files)))
TypeError: 'NoneType' object is not iterable
2022-12-22 09:03:34,609: 'NoneType' object is not iterable (sparamviewer_main.py:807:update_plot, ERROR)
Traceback (most recent call last):
  File "C:\WorkingCopies\Github\sparameterviewer/src\sparamviewer_main.py", line 805, in update_plot
    touched_files = ExpressionParser.eval(raw_exprs, self.files, selected_files, add_to_plot)
  File "C:\WorkingCopies\Github\sparameterviewer/src\lib\expressions\expressions.py", line 68, in eval
    exec(code, vars_global, vars_local)
  File "<string>", line 1, in <module>
  File "C:\WorkingCopies\Github\sparameterviewer/src\lib\expressions\expressions.py", line 48, in nws
    nws = select_networks(available_networks, pattern, single=False)
  File "C:\WorkingCopies\Github\sparameterviewer/src\lib\expressions\expressions.py", line 39, in select_networks
    touch_files(nws)
  File "C:\WorkingCopies\Github\sparameterviewer/src\lib\expressions\expressions.py", line 26, in touch_files
    touched_files = list(set(touched_files.extend(files)))
TypeError: 'NoneType' object is not iterable
2022-12-22 09:03:34,916: 'NoneType' object is not iterable (sparamviewer_main.py:807:update_plot, ERROR)
Traceback (most recent call last):
  File "C:\WorkingCopies\Github\sparameterviewer/src\sparamviewer_main.py", line 805, in update_plot
    touched_files = ExpressionParser.eval(raw_exprs, self.files, selected_files, add_to_plot)
  File "C:\WorkingCopies\Github\sparameterviewer/src\lib\expressions\expressions.py", line 68, in eval
    exec(code, vars_global, vars_local)
  File "<string>", line 1, in <module>
  File "C:\WorkingCopies\Github\sparameterviewer/src\lib\expressions\expressions.py", line 48, in nws
    nws = select_networks(available_networks, pattern, single=False)
  File "C:\WorkingCopies\Github\sparameterviewer/src\lib\expressions\expressions.py", line 39, in select_networks
    touch_files(nws)
  File "C:\WorkingCopies\Github\sparameterviewer/src\lib\expressions\expressions.py", line 26, in touch_files
    touched_files = list(set(touched_files.extend(files)))
TypeError: 'NoneType' object is not iterable
2022-12-22 09:04:15,275: 'NoneType' object is not iterable (sparamviewer_main.py:807:update_plot, ERROR)
Traceback (most recent call last):
  File "C:\WorkingCopies\Github\sparameterviewer/src\sparamviewer_main.py", line 805, in update_plot
    touched_files = ExpressionParser.eval(raw_exprs, self.files, selected_files, add_to_plot)
  File "C:\WorkingCopies\Github\sparameterviewer/src\lib\expressions\expressions.py", line 68, in eval
    exec(code, vars_global, vars_local)
  File "<string>", line 1, in <module>
  File "C:\WorkingCopies\Github\sparameterviewer/src\lib\expressions\expressions.py", line 48, in nws
    nws = select_networks(available_networks, pattern, single=False)
  File "C:\WorkingCopies\Github\sparameterviewer/src\lib\expressions\expressions.py", line 39, in select_networks
    touch_files(nws)
  File "C:\WorkingCopies\Github\sparameterviewer/src\lib\expressions\expressions.py", line 26, in touch_files
    touched_files = list(set(touched_files.extend(files)))
TypeError: 'NoneType' object is not iterable
2022-12-22 09:06:01,124: argument of type 'function' is not iterable (sparamviewer_main.py:807:update_plot, ERROR)
Traceback (most recent call last):
  File "C:\WorkingCopies\Github\sparameterviewer/src\sparamviewer_main.py", line 805, in update_plot
    touched_files = ExpressionParser.eval(raw_exprs, self.files, selected_files, add_to_plot)
  File "C:\WorkingCopies\Github\sparameterviewer/src\lib\expressions\expressions.py", line 70, in eval
    exec(code, vars_global, vars_local)
  File "<string>", line 1, in <module>
  File "C:\WorkingCopies\Github\sparameterviewer/src\lib\expressions\expressions.py", line 50, in nws
    nws = select_networks(available_networks, pattern, single=False)
  File "C:\WorkingCopies\Github\sparameterviewer/src\lib\expressions\expressions.py", line 41, in select_networks
    touch_files(nws)
  File "C:\WorkingCopies\Github\sparameterviewer/src\lib\expressions\expressions.py", line 27, in touch_files
    if f not in touch_files:
TypeError: argument of type 'function' is not iterable
2022-12-22 09:06:01,750: argument of type 'function' is not iterable (sparamviewer_main.py:807:update_plot, ERROR)
Traceback (most recent call last):
  File "C:\WorkingCopies\Github\sparameterviewer/src\sparamviewer_main.py", line 805, in update_plot
    touched_files = ExpressionParser.eval(raw_exprs, self.files, selected_files, add_to_plot)
  File "C:\WorkingCopies\Github\sparameterviewer/src\lib\expressions\expressions.py", line 70, in eval
    exec(code, vars_global, vars_local)
  File "<string>", line 1, in <module>
  File "C:\WorkingCopies\Github\sparameterviewer/src\lib\expressions\expressions.py", line 50, in nws
    nws = select_networks(available_networks, pattern, single=False)
  File "C:\WorkingCopies\Github\sparameterviewer/src\lib\expressions\expressions.py", line 41, in select_networks
    touch_files(nws)
  File "C:\WorkingCopies\Github\sparameterviewer/src\lib\expressions\expressions.py", line 27, in touch_files
    if f not in touch_files:
TypeError: argument of type 'function' is not iterable
2022-12-22 09:08:30,249: 'NoneType' object is not iterable (sparamviewer_main.py:807:update_plot, ERROR)
Traceback (most recent call last):
  File "C:\WorkingCopies\Github\sparameterviewer/src\sparamviewer_main.py", line 805, in update_plot
    touched_files = ExpressionParser.eval(raw_exprs, self.files, selected_files, add_to_plot)
  File "C:\WorkingCopies\Github\sparameterviewer/src\lib\expressions\expressions.py", line 67, in eval
    exec(code, vars_global, vars_local)
  File "<string>", line 1, in <module>
  File "C:\WorkingCopies\Github\sparameterviewer/src\lib\expressions\expressions.py", line 51, in nws
    return select_networks(available_networks, pattern, single=False)
  File "C:\WorkingCopies\Github\sparameterviewer/src\lib\expressions\expressions.py", line 44, in select_networks
    touched_files = list(set(touched_files.extend(nws)))
TypeError: 'NoneType' object is not iterable
2022-12-22 09:08:30,637: 'NoneType' object is not iterable (sparamviewer_main.py:807:update_plot, ERROR)
Traceback (most recent call last):
  File "C:\WorkingCopies\Github\sparameterviewer/src\sparamviewer_main.py", line 805, in update_plot
    touched_files = ExpressionParser.eval(raw_exprs, self.files, selected_files, add_to_plot)
  File "C:\WorkingCopies\Github\sparameterviewer/src\lib\expressions\expressions.py", line 67, in eval
    exec(code, vars_global, vars_local)
  File "<string>", line 1, in <module>
  File "C:\WorkingCopies\Github\sparameterviewer/src\lib\expressions\expressions.py", line 51, in nws
    return select_networks(available_networks, pattern, single=False)
  File "C:\WorkingCopies\Github\sparameterviewer/src\lib\expressions\expressions.py", line 44, in select_networks
    touched_files = list(set(touched_files.extend(nws)))
TypeError: 'NoneType' object is not iterable
2023-01-05 08:01:32,393: Plotting failed: 'Network' object has no attribute 'tag' (sparamviewer_main.py:878:update_plot, ERROR)
Traceback (most recent call last):
  File "C:\WorkingCopies\Github\sparameterviewer/src\sparamviewer_main.py", line 851, in update_plot
    self.update_file_in_list(f)
  File "C:\WorkingCopies\Github\sparameterviewer/src\sparamviewer_main.py", line 622, in update_file_in_list
    tag = file.tag
AttributeError: 'Network' object has no attribute 'tag'
2023-01-05 08:02:57,535: Plotting failed: 'Network' object has no attribute 'tag' (sparamviewer_main.py:878:update_plot, ERROR)
Traceback (most recent call last):
  File "C:\WorkingCopies\Github\sparameterviewer/src\sparamviewer_main.py", line 851, in update_plot
    self.update_file_in_list(f)
  File "C:\WorkingCopies\Github\sparameterviewer/src\sparamviewer_main.py", line 622, in update_file_in_list
    tag = file.tag
AttributeError: 'Network' object has no attribute 'tag'
2023-01-05 08:03:03,463: Plotting failed: 'Network' object has no attribute 'tag' (sparamviewer_main.py:878:update_plot, ERROR)
Traceback (most recent call last):
  File "C:\WorkingCopies\Github\sparameterviewer/src\sparamviewer_main.py", line 851, in update_plot
    self.update_file_in_list(f)
  File "C:\WorkingCopies\Github\sparameterviewer/src\sparamviewer_main.py", line 622, in update_file_in_list
    tag = file.tag
AttributeError: 'Network' object has no attribute 'tag'
2023-01-05 08:03:08,820: Plotting failed: 'Network' object has no attribute 'tag' (sparamviewer_main.py:878:update_plot, ERROR)
Traceback (most recent call last):
  File "C:\WorkingCopies\Github\sparameterviewer/src\sparamviewer_main.py", line 851, in update_plot
    self.update_file_in_list(f)
  File "C:\WorkingCopies\Github\sparameterviewer/src\sparamviewer_main.py", line 622, in update_file_in_list
    tag = file.tag
AttributeError: 'Network' object has no attribute 'tag'
2023-01-05 08:03:09,270: Plotting failed: 'Network' object has no attribute 'tag' (sparamviewer_main.py:878:update_plot, ERROR)
Traceback (most recent call last):
  File "C:\WorkingCopies\Github\sparameterviewer/src\sparamviewer_main.py", line 851, in update_plot
    self.update_file_in_list(f)
  File "C:\WorkingCopies\Github\sparameterviewer/src\sparamviewer_main.py", line 622, in update_file_in_list
    tag = file.tag
AttributeError: 'Network' object has no attribute 'tag'
2023-01-05 08:03:09,433: Plotting failed: 'Network' object has no attribute 'tag' (sparamviewer_main.py:878:update_plot, ERROR)
Traceback (most recent call last):
  File "C:\WorkingCopies\Github\sparameterviewer/src\sparamviewer_main.py", line 851, in update_plot
    self.update_file_in_list(f)
  File "C:\WorkingCopies\Github\sparameterviewer/src\sparamviewer_main.py", line 622, in update_file_in_list
    tag = file.tag
AttributeError: 'Network' object has no attribute 'tag'
2023-01-05 08:03:46,281: Plotting failed: 'Network' object has no attribute 'tag' (sparamviewer_main.py:878:update_plot, ERROR)
Traceback (most recent call last):
  File "C:\WorkingCopies\Github\sparameterviewer/src\sparamviewer_main.py", line 851, in update_plot
    self.update_file_in_list(f)
  File "C:\WorkingCopies\Github\sparameterviewer/src\sparamviewer_main.py", line 622, in update_file_in_list
    tag = file.tag
AttributeError: 'Network' object has no attribute 'tag'
2023-01-05 08:03:51,301: Plotting failed: 'Network' object has no attribute 'tag' (sparamviewer_main.py:878:update_plot, ERROR)
Traceback (most recent call last):
  File "C:\WorkingCopies\Github\sparameterviewer/src\sparamviewer_main.py", line 851, in update_plot
    self.update_file_in_list(f)
  File "C:\WorkingCopies\Github\sparameterviewer/src\sparamviewer_main.py", line 622, in update_file_in_list
    tag = file.tag
AttributeError: 'Network' object has no attribute 'tag'
2023-01-05 08:03:52,346: Plotting failed: 'Network' object has no attribute 'tag' (sparamviewer_main.py:878:update_plot, ERROR)
Traceback (most recent call last):
  File "C:\WorkingCopies\Github\sparameterviewer/src\sparamviewer_main.py", line 851, in update_plot
    self.update_file_in_list(f)
  File "C:\WorkingCopies\Github\sparameterviewer/src\sparamviewer_main.py", line 622, in update_file_in_list
    tag = file.tag
AttributeError: 'Network' object has no attribute 'tag'
2023-01-05 08:03:53,879: Plotting failed: 'Network' object has no attribute 'tag' (sparamviewer_main.py:878:update_plot, ERROR)
Traceback (most recent call last):
  File "C:\WorkingCopies\Github\sparameterviewer/src\sparamviewer_main.py", line 851, in update_plot
    self.update_file_in_list(f)
  File "C:\WorkingCopies\Github\sparameterviewer/src\sparamviewer_main.py", line 622, in update_file_in_list
    tag = file.tag
AttributeError: 'Network' object has no attribute 'tag'
2023-01-05 08:05:20,535: name 'Network' is not defined (sparamviewer_main.py:804:update_plot, ERROR)
Traceback (most recent call last):
  File "C:\WorkingCopies\Github\sparameterviewer/src\sparamviewer_main.py", line 802, in update_plot
    touched_files = ExpressionParser.eval(raw_exprs, self.files, selected_files, add_to_plot)
  File "C:\WorkingCopies\Github\sparameterviewer/src\lib\expressions\expressions.py", line 61, in eval
    exec(code, vars_global, vars_local)
  File "<string>", line 1, in <module>
NameError: name 'Network' is not defined
2023-01-05 08:05:26,865: Invalid type to init Network object (<a>) (sparamviewer_main.py:804:update_plot, ERROR)
Traceback (most recent call last):
  File "C:\WorkingCopies\Github\sparameterviewer/src\sparamviewer_main.py", line 802, in update_plot
    touched_files = ExpressionParser.eval(raw_exprs, self.files, selected_files, add_to_plot)
  File "C:\WorkingCopies\Github\sparameterviewer/src\lib\expressions\expressions.py", line 61, in eval
    exec(code, vars_global, vars_local)
  File "<string>", line 1, in <module>
  File "C:\WorkingCopies\Github\sparameterviewer/src\lib\expressions\networks.py", line 242, in __init__
    self.nws = [Network(nw) for nw in nws]
  File "C:\WorkingCopies\Github\sparameterviewer/src\lib\expressions\networks.py", line 242, in <listcomp>
    self.nws = [Network(nw) for nw in nws]
  File "C:\WorkingCopies\Github\sparameterviewer/src\lib\expressions\networks.py", line 25, in __init__
    raise ValueError(f'Invalid type to init Network object (<{nw}>)')
ValueError: Invalid type to init Network object (<a>)
2023-01-05 08:10:10,270: Invalid type to init Network object (<a>) (sparamviewer_main.py:804:update_plot, ERROR)
Traceback (most recent call last):
  File "C:\WorkingCopies\Github\sparameterviewer/src\sparamviewer_main.py", line 802, in update_plot
    touched_files = ExpressionParser.eval(raw_exprs, self.files, selected_files, add_to_plot)
  File "C:\WorkingCopies\Github\sparameterviewer/src\lib\expressions\expressions.py", line 61, in eval
    exec(code, vars_global, vars_local)
  File "<string>", line 1, in <module>
  File "C:\WorkingCopies\Github\sparameterviewer/src\lib\expressions\networks.py", line 242, in __init__
    self.nws = [Network(nw) for nw in nws]
  File "C:\WorkingCopies\Github\sparameterviewer/src\lib\expressions\networks.py", line 242, in <listcomp>
    self.nws = [Network(nw) for nw in nws]
  File "C:\WorkingCopies\Github\sparameterviewer/src\lib\expressions\networks.py", line 25, in __init__
    raise ValueError(f'Invalid type to init Network object (<{nw}>)')
ValueError: Invalid type to init Network object (<a>)
2023-01-05 08:10:10,668: Invalid type to init Network object (<a>) (sparamviewer_main.py:804:update_plot, ERROR)
Traceback (most recent call last):
  File "C:\WorkingCopies\Github\sparameterviewer/src\sparamviewer_main.py", line 802, in update_plot
    touched_files = ExpressionParser.eval(raw_exprs, self.files, selected_files, add_to_plot)
  File "C:\WorkingCopies\Github\sparameterviewer/src\lib\expressions\expressions.py", line 61, in eval
    exec(code, vars_global, vars_local)
  File "<string>", line 1, in <module>
  File "C:\WorkingCopies\Github\sparameterviewer/src\lib\expressions\networks.py", line 242, in __init__
    self.nws = [Network(nw) for nw in nws]
  File "C:\WorkingCopies\Github\sparameterviewer/src\lib\expressions\networks.py", line 242, in <listcomp>
    self.nws = [Network(nw) for nw in nws]
  File "C:\WorkingCopies\Github\sparameterviewer/src\lib\expressions\networks.py", line 25, in __init__
    raise ValueError(f'Invalid type to init Network object (<{nw}>)')
ValueError: Invalid type to init Network object (<a>)
2023-02-08 15:00:17,059: Exporting failed: frombuffer() missing 2 required positional arguments: 'size' and 'data' (main_window.py:543:on_save_plot_graphic, ERROR)
Traceback (most recent call last):
  File "C:\WorkingCopies\Github\sparameterviewer/src\gui\main_window.py", line 520, in on_save_plot_graphic
    image = Image.frombuffer(buf)
TypeError: frombuffer() missing 2 required positional arguments: 'size' and 'data'
2023-02-08 15:01:52,010: Exporting failed: frombytes() missing 2 required positional arguments: 'size' and 'data' (main_window.py:543:on_save_plot_graphic, ERROR)
Traceback (most recent call last):
  File "C:\WorkingCopies\Github\sparameterviewer/src\gui\main_window.py", line 520, in on_save_plot_graphic
    image = Image.frombytes(buf.getvalue())
TypeError: frombytes() missing 2 required positional arguments: 'size' and 'data'
2023-02-08 15:05:53,758: Exporting failed: 'utf-8' codec can't decode byte 0x89 in position 0: invalid start byte (main_window.py:547:on_save_plot_graphic, ERROR)
Traceback (most recent call last):
  File "C:\WorkingCopies\Github\sparameterviewer/src\gui\main_window.py", line 521, in on_save_plot_graphic
    image = Image.open(buf.getvalue())
  File "C:\Python37\lib\site-packages\PIL\Image.py", line 3131, in open
    fp = builtins.open(filename, "rb")
UnicodeDecodeError: 'utf-8' codec can't decode byte 0x89 in position 0: invalid start byte
2023-02-08 15:07:24,030: Exporting failed: 'utf-8' codec can't decode byte 0x97 in position 22: invalid start byte (main_window.py:547:on_save_plot_graphic, ERROR)
Traceback (most recent call last):
  File "C:\WorkingCopies\Github\sparameterviewer/src\gui\main_window.py", line 521, in on_save_plot_graphic
    image = Image.open(buf.getvalue()[1:])
  File "C:\Python37\lib\site-packages\PIL\Image.py", line 3131, in open
    fp = builtins.open(filename, "rb")
UnicodeDecodeError: 'utf-8' codec can't decode byte 0x97 in position 22: invalid start byte
2023-02-08 15:09:02,268: Exporting failed: Format 'bmp' is not supported (supported formats: eps, jpeg, jpg, pdf, pgf, png, ps, raw, rgba, svg, svgz, tif, tiff) (main_window.py:547:on_save_plot_graphic, ERROR)
Traceback (most recent call last):
  File "C:\WorkingCopies\Github\sparameterviewer/src\gui\main_window.py", line 520, in on_save_plot_graphic
    self.plot.fig.savefig(buf, format='bmp')
  File "C:\Python37\lib\site-packages\matplotlib\figure.py", line 3058, in savefig
    self.canvas.print_figure(fname, **kwargs)
  File "C:\Python37\lib\site-packages\matplotlib\backend_bases.py", line 2259, in print_figure
    canvas = self._get_output_canvas(backend, format)
  File "C:\Python37\lib\site-packages\matplotlib\backend_bases.py", line 2190, in _get_output_canvas
    .format(fmt, ", ".join(sorted(self.get_supported_filetypes()))))
ValueError: Format 'bmp' is not supported (supported formats: eps, jpeg, jpg, pdf, pgf, png, ps, raw, rgba, svg, svgz, tif, tiff)
2023-02-08 15:11:13,624: Exporting failed: name 'fself' is not defined (main_window.py:552:on_save_plot_graphic, ERROR)
Traceback (most recent call last):
  File "C:\WorkingCopies\Github\sparameterviewer/src\gui\main_window.py", line 521, in on_save_plot_graphic
    buf = fself.plot.fig.canvas.buffer_rgba()
NameError: name 'fself' is not defined
2023-02-08 15:11:33,937: Exporting failed: 'memoryview' object has no attribute 'write' (main_window.py:552:on_save_plot_graphic, ERROR)
Traceback (most recent call last):
  File "C:\WorkingCopies\Github\sparameterviewer/src\gui\main_window.py", line 525, in on_save_plot_graphic
    im.transpose(Image.FLIP_TOP_BOTTOM).convert("RGB").save(buf, "BMP")
  File "C:\Python37\lib\site-packages\PIL\Image.py", line 2353, in save
    save_handler(self, fp, filename)
  File "C:\Python37\lib\site-packages\PIL\BmpImagePlugin.py", line 415, in _save
    fp.write(
AttributeError: 'memoryview' object has no attribute 'write'
2023-02-09 11:14:58,730: Exporting failed: to_pandas() missing 1 required positional argument: 'filename' (main_window.py:529:on_save_plot_graphic, ERROR)
Traceback (most recent call last):
  File "C:\WorkingCopies\Github\sparameterviewer/src\gui\main_window.py", line 515, in on_save_plot_graphic
    df = DataExport.to_pandas(self.plot.plots)
TypeError: to_pandas() missing 1 required positional argument: 'filename'
2023-02-09 11:27:03,407: Exporting failed: The truth value of an array with more than one element is ambiguous. Use a.any() or a.all() (main_window.py:529:on_save_plot_graphic, ERROR)
Traceback (most recent call last):
  File "C:\WorkingCopies\Github\sparameterviewer/src\gui\main_window.py", line 515, in on_save_plot_graphic
    df = DataExport.to_pandas(self.plot.plots)
  File "C:\WorkingCopies\Github\sparameterviewer/src\lib\data_export.py", line 103, in to_pandas
    if (first_xname==xname) and np.equal(first_xdata, plot.y.values):
ValueError: The truth value of an array with more than one element is ambiguous. Use a.any() or a.all()
2023-02-09 11:27:35,967: Exporting failed: The truth value of an array with more than one element is ambiguous. Use a.any() or a.all() (main_window.py:529:on_save_plot_graphic, ERROR)
Traceback (most recent call last):
  File "C:\WorkingCopies\Github\sparameterviewer/src\gui\main_window.py", line 515, in on_save_plot_graphic
    df = DataExport.to_pandas(self.plot.plots)
  File "C:\WorkingCopies\Github\sparameterviewer/src\lib\data_export.py", line 103, in to_pandas
    if (first_xname==xname) and np.equal(first_xdata, plot.y.values):
ValueError: The truth value of an array with more than one element is ambiguous. Use a.any() or a.all()
2023-02-09 15:29:20,055: Copying plot to clipboard failed: Length of values (64) does not match length of index (1870) (main_window.py:568:on_copy_plot_data_to_clipboard, ERROR)
Traceback (most recent call last):
  File "C:\WorkingCopies\Github\sparameterviewer/src\gui\main_window.py", line 564, in on_copy_plot_data_to_clipboard
    df = DataExport.to_pandas(self.plot.plots)
  File "C:\WorkingCopies\Github\sparameterviewer/src\lib\data_export.py", line 104, in to_pandas
    df[yname] = plot.y.values # same x-axis -> just add another column
  File "C:\Python37\lib\site-packages\pandas\core\frame.py", line 3612, in __setitem__
    self._set_item(key, value)
  File "C:\Python37\lib\site-packages\pandas\core\frame.py", line 3784, in _set_item
    value = self._sanitize_column(value)
  File "C:\Python37\lib\site-packages\pandas\core\frame.py", line 4509, in _sanitize_column
    com.require_length_match(value, self.index)
  File "C:\Python37\lib\site-packages\pandas\core\common.py", line 532, in require_length_match
    "Length of values "
ValueError: Length of values (64) does not match length of index (1870)
2023-02-09 16:47:13,466: Copying plot to clipboard failed: array([9.00000000e+09, 9.04119142e+09, 9.08257136e+09, 9.12414069e+09,
       9.16590027e+09, 9.20785098e+09, 9.24999370e+09, 9.29232929e+09,
       9.33485864e+09, 9.37758265e+09, 9.42050219e+09, 9.46361817e+09,
       9.50693149e+09, 9.55044304e+09, 9.59415373e+09, 9.63806448e+09,
       9.68217621e+09, 9.72648982e+09, 9.77100626e+09, 9.81572643e+09,
       9.86065128e+09, 9.90578175e+09, 9.95111877e+09, 9.99666328e+09,
       1.00424163e+10, 1.00883786e+10, 1.01345514e+10, 1.01809354e+10,
       1.02275318e+10, 1.02743414e+10, 1.03213652e+10, 1.03686043e+10,
       1.04160596e+10, 1.04637320e+10, 1.05116227e+10, 1.05597325e+10,
       1.06080626e+10, 1.06566138e+10, 1.07053873e+10, 1.07543839e+10,
       1.08036049e+10, 1.08530511e+10, 1.09027236e+10, 1.09526234e+10,
       1.10027516e+10, 1.10531093e+10, 1.11036974e+10, 1.11545171e+10,
       1.12055694e+10, 1.12568553e+10, 1.13083759e+10, 1.13601324e+10,
       1.14121257e+10, 1.14643570e+10, 1.15168273e+10, 1.15695378e+10,
       1.16224895e+10, 1.16756836e+10, 1.17291212e+10, 1.17828033e+10,
       1.18367311e+10, 1.18909058e+10, 1.19453283e+10, 1.20000000e+10]) (main_window.py:568:on_copy_plot_data_to_clipboard, ERROR)
Traceback (most recent call last):
  File "C:\WorkingCopies\Github\sparameterviewer/src\gui\main_window.py", line 564, in on_copy_plot_data_to_clipboard
    df = DataExport.to_pandas(self.plot.plots)
  File "C:\WorkingCopies\Github\sparameterviewer/src\lib\data_export.py", line 106, in to_pandas
    df = df.merge(new_rows, left_on=first_xname, right_on=first_xname, how='outer').sort_values(by=first_xdata)
  File "C:\Python37\lib\site-packages\pandas\util\_decorators.py", line 311, in wrapper
    return func(*args, **kwargs)
  File "C:\Python37\lib\site-packages\pandas\core\frame.py", line 6259, in sort_values
    k = self._get_label_or_level_values(by, axis=axis)
  File "C:\Python37\lib\site-packages\pandas\core\generic.py", line 1779, in _get_label_or_level_values
    raise KeyError(key)
KeyError: array([9.00000000e+09, 9.04119142e+09, 9.08257136e+09, 9.12414069e+09,
       9.16590027e+09, 9.20785098e+09, 9.24999370e+09, 9.29232929e+09,
       9.33485864e+09, 9.37758265e+09, 9.42050219e+09, 9.46361817e+09,
       9.50693149e+09, 9.55044304e+09, 9.59415373e+09, 9.63806448e+09,
       9.68217621e+09, 9.72648982e+09, 9.77100626e+09, 9.81572643e+09,
       9.86065128e+09, 9.90578175e+09, 9.95111877e+09, 9.99666328e+09,
       1.00424163e+10, 1.00883786e+10, 1.01345514e+10, 1.01809354e+10,
       1.02275318e+10, 1.02743414e+10, 1.03213652e+10, 1.03686043e+10,
       1.04160596e+10, 1.04637320e+10, 1.05116227e+10, 1.05597325e+10,
       1.06080626e+10, 1.06566138e+10, 1.07053873e+10, 1.07543839e+10,
       1.08036049e+10, 1.08530511e+10, 1.09027236e+10, 1.09526234e+10,
       1.10027516e+10, 1.10531093e+10, 1.11036974e+10, 1.11545171e+10,
       1.12055694e+10, 1.12568553e+10, 1.13083759e+10, 1.13601324e+10,
       1.14121257e+10, 1.14643570e+10, 1.15168273e+10, 1.15695378e+10,
       1.16224895e+10, 1.16756836e+10, 1.17291212e+10, 1.17828033e+10,
       1.18367311e+10, 1.18909058e+10, 1.19453283e+10, 1.20000000e+10])
2023-02-09 16:47:31,457: Copying plot to clipboard failed: array([9.00000000e+09, 9.04119142e+09, 9.08257136e+09, 9.12414069e+09,
       9.16590027e+09, 9.20785098e+09, 9.24999370e+09, 9.29232929e+09,
       9.33485864e+09, 9.37758265e+09, 9.42050219e+09, 9.46361817e+09,
       9.50693149e+09, 9.55044304e+09, 9.59415373e+09, 9.63806448e+09,
       9.68217621e+09, 9.72648982e+09, 9.77100626e+09, 9.81572643e+09,
       9.86065128e+09, 9.90578175e+09, 9.95111877e+09, 9.99666328e+09,
       1.00424163e+10, 1.00883786e+10, 1.01345514e+10, 1.01809354e+10,
       1.02275318e+10, 1.02743414e+10, 1.03213652e+10, 1.03686043e+10,
       1.04160596e+10, 1.04637320e+10, 1.05116227e+10, 1.05597325e+10,
       1.06080626e+10, 1.06566138e+10, 1.07053873e+10, 1.07543839e+10,
       1.08036049e+10, 1.08530511e+10, 1.09027236e+10, 1.09526234e+10,
       1.10027516e+10, 1.10531093e+10, 1.11036974e+10, 1.11545171e+10,
       1.12055694e+10, 1.12568553e+10, 1.13083759e+10, 1.13601324e+10,
       1.14121257e+10, 1.14643570e+10, 1.15168273e+10, 1.15695378e+10,
       1.16224895e+10, 1.16756836e+10, 1.17291212e+10, 1.17828033e+10,
       1.18367311e+10, 1.18909058e+10, 1.19453283e+10, 1.20000000e+10]) (main_window.py:568:on_copy_plot_data_to_clipboard, ERROR)
Traceback (most recent call last):
  File "C:\WorkingCopies\Github\sparameterviewer/src\gui\main_window.py", line 564, in on_copy_plot_data_to_clipboard
    df = DataExport.to_pandas(self.plot.plots)
  File "C:\WorkingCopies\Github\sparameterviewer/src\lib\data_export.py", line 106, in to_pandas
    df = df.merge(new_rows, left_on=first_xname, right_on=first_xname, how='outer').sort_values(by=first_xdata)
  File "C:\Python37\lib\site-packages\pandas\util\_decorators.py", line 311, in wrapper
    return func(*args, **kwargs)
  File "C:\Python37\lib\site-packages\pandas\core\frame.py", line 6259, in sort_values
    k = self._get_label_or_level_values(by, axis=axis)
  File "C:\Python37\lib\site-packages\pandas\core\generic.py", line 1779, in _get_label_or_level_values
    raise KeyError(key)
KeyError: array([9.00000000e+09, 9.04119142e+09, 9.08257136e+09, 9.12414069e+09,
       9.16590027e+09, 9.20785098e+09, 9.24999370e+09, 9.29232929e+09,
       9.33485864e+09, 9.37758265e+09, 9.42050219e+09, 9.46361817e+09,
       9.50693149e+09, 9.55044304e+09, 9.59415373e+09, 9.63806448e+09,
       9.68217621e+09, 9.72648982e+09, 9.77100626e+09, 9.81572643e+09,
       9.86065128e+09, 9.90578175e+09, 9.95111877e+09, 9.99666328e+09,
       1.00424163e+10, 1.00883786e+10, 1.01345514e+10, 1.01809354e+10,
       1.02275318e+10, 1.02743414e+10, 1.03213652e+10, 1.03686043e+10,
       1.04160596e+10, 1.04637320e+10, 1.05116227e+10, 1.05597325e+10,
       1.06080626e+10, 1.06566138e+10, 1.07053873e+10, 1.07543839e+10,
       1.08036049e+10, 1.08530511e+10, 1.09027236e+10, 1.09526234e+10,
       1.10027516e+10, 1.10531093e+10, 1.11036974e+10, 1.11545171e+10,
       1.12055694e+10, 1.12568553e+10, 1.13083759e+10, 1.13601324e+10,
       1.14121257e+10, 1.14643570e+10, 1.15168273e+10, 1.15695378e+10,
       1.16224895e+10, 1.16756836e+10, 1.17291212e+10, 1.17828033e+10,
       1.18367311e+10, 1.18909058e+10, 1.19453283e+10, 1.20000000e+10])
2023-03-06 15:46:45,308: Unable to init main dialog: 'SparamviewerMainDialog' object has no attribute 'hide_single_legend' (main_window.py:168:__init__, ERROR)
Traceback (most recent call last):
  File "C:\WorkingCopies\Github\sparameterviewer/src\gui\main_window.py", line 51, in __init__
    self.hide_single_legend.set('1' if Settings.hide_single_item_legend else '0')
AttributeError: 'SparamviewerMainDialog' object has no attribute 'hide_single_legend'
2023-03-06 16:15:39,287: Plotting failed: __init__() missing 2 required positional arguments: 'z_qty' and 'z_fmt' (main_window.py:926:update_plot, ERROR)
Traceback (most recent call last):
  File "C:\WorkingCopies\Github\sparameterviewer/src\gui\main_window.py", line 779, in update_plot
    self.plot = PlotHelper(self.fig, True, False, '', SiFmt(), False, '', SiFmt(), False, smith_type=smith_type, smith_z=smith_z, **common_plot_args)
TypeError: __init__() missing 2 required positional arguments: 'z_qty' and 'z_fmt'
2023-03-06 16:15:39,296: Unable to init main dialog: __init__() missing 2 required positional arguments: 'z_qty' and 'z_fmt' (main_window.py:168:__init__, ERROR)
Traceback (most recent call last):
  File "C:\WorkingCopies\Github\sparameterviewer/src\gui\main_window.py", line 164, in __init__
    self.update_plot()
  File "C:\WorkingCopies\Github\sparameterviewer/src\gui\main_window.py", line 927, in update_plot
    raise ex
  File "C:\WorkingCopies\Github\sparameterviewer/src\gui\main_window.py", line 779, in update_plot
    self.plot = PlotHelper(self.fig, True, False, '', SiFmt(), False, '', SiFmt(), False, smith_type=smith_type, smith_z=smith_z, **common_plot_args)
TypeError: __init__() missing 2 required positional arguments: 'z_qty' and 'z_fmt'
2023-03-06 16:15:39,333: Plotting failed: __init__() missing 2 required positional arguments: 'z_qty' and 'z_fmt' (main_window.py:926:update_plot, ERROR)
Traceback (most recent call last):
  File "C:\WorkingCopies\Github\sparameterviewer/src\gui\main_window.py", line 164, in __init__
    self.update_plot()
  File "C:\WorkingCopies\Github\sparameterviewer/src\gui\main_window.py", line 927, in update_plot
    raise ex
  File "C:\WorkingCopies\Github\sparameterviewer/src\gui\main_window.py", line 779, in update_plot
    self.plot = PlotHelper(self.fig, True, False, '', SiFmt(), False, '', SiFmt(), False, smith_type=smith_type, smith_z=smith_z, **common_plot_args)
TypeError: __init__() missing 2 required positional arguments: 'z_qty' and 'z_fmt'

During handling of the above exception, another exception occurred:

Traceback (most recent call last):
  File "C:\WorkingCopies\Github\sparameterviewer/src\gui\main_window.py", line 798, in update_plot
    self.plot = PlotHelper(self.fig, False, False, xq, xf, xl, yq, yf, yl, **common_plot_args)
TypeError: __init__() missing 2 required positional arguments: 'z_qty' and 'z_fmt'
2023-03-06 16:23:21,014: Plotting failed: 'ItemToPlot' object is not subscriptable (main_window.py:926:update_plot, ERROR)
Traceback (most recent call last):
  File "C:\WorkingCopies\Github\sparameterviewer/src\gui\main_window.py", line 901, in update_plot
    self.plot.render()
  File "C:\WorkingCopies\Github\sparameterviewer/src\lib\plot.py", line 201, in render
    labels = [i[2] for i in self.items_to_plot]
  File "C:\WorkingCopies\Github\sparameterviewer/src\lib\plot.py", line 201, in <listcomp>
    labels = [i[2] for i in self.items_to_plot]
TypeError: 'ItemToPlot' object is not subscriptable
2023-03-06 16:23:21,030: Unable to init main dialog: 'ItemToPlot' object is not subscriptable (main_window.py:168:__init__, ERROR)
Traceback (most recent call last):
  File "C:\WorkingCopies\Github\sparameterviewer/src\gui\main_window.py", line 164, in __init__
    self.update_plot()
  File "C:\WorkingCopies\Github\sparameterviewer/src\gui\main_window.py", line 927, in update_plot
    raise ex
  File "C:\WorkingCopies\Github\sparameterviewer/src\gui\main_window.py", line 901, in update_plot
    self.plot.render()
  File "C:\WorkingCopies\Github\sparameterviewer/src\lib\plot.py", line 201, in render
    labels = [i[2] for i in self.items_to_plot]
  File "C:\WorkingCopies\Github\sparameterviewer/src\lib\plot.py", line 201, in <listcomp>
    labels = [i[2] for i in self.items_to_plot]
TypeError: 'ItemToPlot' object is not subscriptable
2023-03-06 16:23:21,337: Plotting failed: 'ItemToPlot' object is not subscriptable (main_window.py:926:update_plot, ERROR)
Traceback (most recent call last):
  File "C:\WorkingCopies\Github\sparameterviewer/src\gui\main_window.py", line 164, in __init__
    self.update_plot()
  File "C:\WorkingCopies\Github\sparameterviewer/src\gui\main_window.py", line 927, in update_plot
    raise ex
  File "C:\WorkingCopies\Github\sparameterviewer/src\gui\main_window.py", line 901, in update_plot
    self.plot.render()
  File "C:\WorkingCopies\Github\sparameterviewer/src\lib\plot.py", line 201, in render
    labels = [i[2] for i in self.items_to_plot]
  File "C:\WorkingCopies\Github\sparameterviewer/src\lib\plot.py", line 201, in <listcomp>
    labels = [i[2] for i in self.items_to_plot]
TypeError: 'ItemToPlot' object is not subscriptable

During handling of the above exception, another exception occurred:

Traceback (most recent call last):
  File "C:\WorkingCopies\Github\sparameterviewer/src\gui\main_window.py", line 901, in update_plot
    self.plot.render()
  File "C:\WorkingCopies\Github\sparameterviewer/src\lib\plot.py", line 201, in render
    labels = [i[2] for i in self.items_to_plot]
  File "C:\WorkingCopies\Github\sparameterviewer/src\lib\plot.py", line 201, in <listcomp>
    labels = [i[2] for i in self.items_to_plot]
TypeError: 'ItemToPlot' object is not subscriptable
2023-03-06 16:23:46,733: Plotting failed: 'ItemToPlot' object has no attribute 'label' (main_window.py:926:update_plot, ERROR)
Traceback (most recent call last):
  File "C:\WorkingCopies\Github\sparameterviewer/src\gui\main_window.py", line 901, in update_plot
    self.plot.render()
  File "C:\WorkingCopies\Github\sparameterviewer/src\lib\plot.py", line 201, in render
    labels = [i.label for i in self.items_to_plot]
  File "C:\WorkingCopies\Github\sparameterviewer/src\lib\plot.py", line 201, in <listcomp>
    labels = [i.label for i in self.items_to_plot]
AttributeError: 'ItemToPlot' object has no attribute 'label'
2023-03-06 16:23:46,743: Unable to init main dialog: 'ItemToPlot' object has no attribute 'label' (main_window.py:168:__init__, ERROR)
Traceback (most recent call last):
  File "C:\WorkingCopies\Github\sparameterviewer/src\gui\main_window.py", line 164, in __init__
    self.update_plot()
  File "C:\WorkingCopies\Github\sparameterviewer/src\gui\main_window.py", line 927, in update_plot
    raise ex
  File "C:\WorkingCopies\Github\sparameterviewer/src\gui\main_window.py", line 901, in update_plot
    self.plot.render()
  File "C:\WorkingCopies\Github\sparameterviewer/src\lib\plot.py", line 201, in render
    labels = [i.label for i in self.items_to_plot]
  File "C:\WorkingCopies\Github\sparameterviewer/src\lib\plot.py", line 201, in <listcomp>
    labels = [i.label for i in self.items_to_plot]
AttributeError: 'ItemToPlot' object has no attribute 'label'
2023-03-06 16:23:46,902: Plotting failed: 'ItemToPlot' object has no attribute 'label' (main_window.py:926:update_plot, ERROR)
Traceback (most recent call last):
  File "C:\WorkingCopies\Github\sparameterviewer/src\gui\main_window.py", line 164, in __init__
    self.update_plot()
  File "C:\WorkingCopies\Github\sparameterviewer/src\gui\main_window.py", line 927, in update_plot
    raise ex
  File "C:\WorkingCopies\Github\sparameterviewer/src\gui\main_window.py", line 901, in update_plot
    self.plot.render()
  File "C:\WorkingCopies\Github\sparameterviewer/src\lib\plot.py", line 201, in render
    labels = [i.label for i in self.items_to_plot]
  File "C:\WorkingCopies\Github\sparameterviewer/src\lib\plot.py", line 201, in <listcomp>
    labels = [i.label for i in self.items_to_plot]
AttributeError: 'ItemToPlot' object has no attribute 'label'

During handling of the above exception, another exception occurred:

Traceback (most recent call last):
  File "C:\WorkingCopies\Github\sparameterviewer/src\gui\main_window.py", line 901, in update_plot
    self.plot.render()
  File "C:\WorkingCopies\Github\sparameterviewer/src\lib\plot.py", line 201, in render
    labels = [i.label for i in self.items_to_plot]
  File "C:\WorkingCopies\Github\sparameterviewer/src\lib\plot.py", line 201, in <listcomp>
    labels = [i.label for i in self.items_to_plot]
AttributeError: 'ItemToPlot' object has no attribute 'label'
2023-03-06 16:31:03,313: Plotting failed: __init__() got an unexpected keyword argument 'q_fmot' (main_window.py:933:update_plot, ERROR)
Traceback (most recent call last):
  File "C:\WorkingCopies\Github\sparameterviewer/src\gui\main_window.py", line 786, in update_plot
    self.plot = PlotHelper(fig=self.fig, smith=True, polar=False, x_qty='', q_fmot=SiFmt(), x_log=False, y_qty='', y_fmt=SiFmt(), y_log=False, z_qty='Frequency', z_fmt=SiFmt(unit='Hz'), smith_type=smith_type, smith_z=smith_z, **common_plot_args)
TypeError: __init__() got an unexpected keyword argument 'q_fmot'
2023-03-06 16:31:45,981: Plotting failed: __init__() got an unexpected keyword argument 'q_fmot' (main_window.py:933:update_plot, ERROR)
Traceback (most recent call last):
  File "C:\WorkingCopies\Github\sparameterviewer/src\gui\main_window.py", line 786, in update_plot
    self.plot = PlotHelper(fig=self.fig, smith=True, polar=False, x_qty='', q_fmot=SiFmt(), x_log=False, y_qty='', y_fmt=SiFmt(), y_log=False, z_qty='Frequency', z_fmt=SiFmt(unit='Hz'), smith_type=smith_type, smith_z=smith_z, **common_plot_args)
TypeError: __init__() got an unexpected keyword argument 'q_fmot'
2023-03-06 16:31:45,989: Unable to init main dialog: __init__() got an unexpected keyword argument 'q_fmot' (main_window.py:168:__init__, ERROR)
Traceback (most recent call last):
  File "C:\WorkingCopies\Github\sparameterviewer/src\gui\main_window.py", line 164, in __init__
    self.update_plot()
  File "C:\WorkingCopies\Github\sparameterviewer/src\gui\main_window.py", line 934, in update_plot
    raise ex
  File "C:\WorkingCopies\Github\sparameterviewer/src\gui\main_window.py", line 786, in update_plot
    self.plot = PlotHelper(fig=self.fig, smith=True, polar=False, x_qty='', q_fmot=SiFmt(), x_log=False, y_qty='', y_fmt=SiFmt(), y_log=False, z_qty='Frequency', z_fmt=SiFmt(unit='Hz'), smith_type=smith_type, smith_z=smith_z, **common_plot_args)
TypeError: __init__() got an unexpected keyword argument 'q_fmot'
2023-03-06 16:32:33,384: Plotting failed: __init__() got an unexpected keyword argument 'q_fmt' (main_window.py:933:update_plot, ERROR)
Traceback (most recent call last):
  File "C:\WorkingCopies\Github\sparameterviewer/src\gui\main_window.py", line 786, in update_plot
    self.plot = PlotHelper(fig=self.fig, smith=True, polar=False, x_qty='', q_fmt=SiFmt(), x_log=False, y_qty='', y_fmt=SiFmt(), y_log=False, z_qty='Frequency', z_fmt=SiFmt(unit='Hz'), smith_type=smith_type, smith_z=smith_z, **common_plot_args)
TypeError: __init__() got an unexpected keyword argument 'q_fmt'
2023-03-31 13:10:49,114: Starting splash (sparamviewer.py:39:<module>, ERROR)
2023-03-31 13:10:49,117: Unable to start splash screen: No module named 'pyi_splash' (sparamviewer.py:46:<module>, ERROR)
2023-06-05 16:07:16,248: Unable to init main dialog: 'SparamviewerMainDialog' object has no attribute 'hide_single_legend' (main_window.py:169:__init__, ERROR)
Traceback (most recent call last):
  File "C:\WorkingCopies\Github\sparameterviewer/src\gui\main_window.py", line 52, in __init__
    self.hide_single_legend.set('1' if Settings.hide_single_item_legend else '0')
    ^^^^^^^^^^^^^^^^^^^^^^^
AttributeError: 'SparamviewerMainDialog' object has no attribute 'hide_single_legend'
